Workbook

Sheet Preenchimento
A1: Tabela de Preenchimento de Notas | H1: DÚVIDAS ENTRAR EM CONTATO: Manoela Pugliese SECRETÁRIA GERAL ADJUNTA RH@INTERNATIONALI.COM.BR 63 992794306
C4: Gestor | D4: Secretário | E4: Trainee | F4: Número de Treinamentos
A5: Nome
A6: Telefone | F6: Noite Cultural
A7: E-mail
B9: Nome | C9: Série/turma | D9: Função | E9: Grupo Noite Cultural | F9: E-mail | G9: Telefone | H9: Unidade Escolar
A10: 1
A11: 2
A12: 3
A13: 4
A14: 5
A15: 6
A16: 7
A17: 8
A18: 9
A19: 10
A20: 11
A21: 12
... A109: 100

Sheet Treinamentos
D1: =IF(Preenchimento!F5="online","Online","Treinamento 1") -> Treinamento 1 | E1: =IF(Preenchimento!F5="online","-",IF(Preenchimento!F5=1,"-","Treinamento 2")) -> Treinamento 2
B2: Nome | C2: Função | D2: =IF(OR(D1="treinamento 1",D1="online"),"Presença","-") -> Presença | E2: =IF(E1="-","-","Presença") -> Presença | H2: Média
A3: 1 | B3: =IF(Preenchimento!B10="","-",Preenchimento!B10) -> - | C3: =IF(Preenchimento!D10="","-",Preenchimento!D10) -> - | F3: =IF(D3="P",10,IF(D3="F",0,"-")) -> - | G3: =IF(E3="P",10,IF(E3="F",0,"-")) -> - | H3: =IF(Preenchimento!$F$5="Online","Online",IF(Preenchimento!$F$5=1,F3,IF(Preenchimento!$F$5=2,(SUM(F3:G3)/2),"-"))) -> -
A4: 2 | B4: =IF(Preenchimento!B11="","-",Preenchimento!B11) -> - | C4: =IF(Preenchimento!D11="","-",Preenchimento!D11) -> - | F4: =IF(D4="P",10,IF(D4="F",0,"-")) -> - | G4: =IF(E4="P",10,IF(E4="F",0,"-")) -> - | H4: =IF(Preenchimento!$F$5="Online","Online",IF(Preenchimento!$F$5=1,F4,IF(Preenchimento!$F$5=2,(SUM(F4:G4)/2),"-"))) -> -
A5: 3 | B5: =IF(Preenchimento!B12="","-",Preenchimento!B12) -> - | C5: =IF(Preenchimento!D12="","-",Preenchimento!D12) -> - | F5: =IF(D5="P",10,IF(D5="F",0,"-")) -> - | G5: =IF(E5="P",10,IF(E5="F",0,"-")) -> - | H5: =IF(Preenchimento!$F$5="Online","Online",IF(Preenchimento!$F$5=1,F5,IF(Preenchimento!$F$5=2,(SUM(F5:G5)/2),"-"))) -> -
A6: 4 | B6: =IF(Preenchimento!B13="","-",Preenchimento!B13) -> - | C6: =IF(Preenchimento!D13="","-",Preenchimento!D13) -> - | F6: =IF(D6="P",10,IF(D6="F",0,"-")) -> - | G6: =IF(E6="P",10,IF(E6="F",0,"-")) -> - | H6: =IF(Preenchimento!$F$5="Online","Online",IF(Preenchimento!$F$5=1,F6,IF(Preenchimento!$F$5=2,(SUM(F6:G6)/2),"-"))) -> -
A7: 5 | B7: =IF(Preenchimento!B14="","-",Preenchimento!B14) -> - | C7: =IF(Preenchimento!D14="","-",Preenchimento!D14) -> - | F7: =IF(D7="P",10,IF(D7="F",0,"-")) -> - | G7: =IF(E7="P",10,IF(E7="F",0,"-")) -> - | H7: =IF(Preenchimento!$F$5="Online","Online",IF(Preenchimento!$F$5=1,F7,IF(Preenchimento!$F$5=2,(SUM(F7:G7)/2),"-"))) -> -
A8: 6 | B8: =IF(Preenchimento!B15="","-",Preenchimento!B15) -> - | C8: =IF(Preenchimento!D15="","-",Preenchimento!D15) -> - | F8: =IF(D8="P",10,IF(D8="F",0,"-")) -> - | G8: =IF(E8="P",10,IF(E8="F",0,"-")) -> - | H8: =IF(Preenchimento!$F$5="Online","Online",IF(Preenchimento!$F$5=1,F8,IF(Preenchimento!$F$5=2,(SUM(F8:G8)/2),"-"))) -> -
A9: 7 | B9: =IF(Preenchimento!B16="","-",Preenchimento!B16) -> - | C9: =IF(Preenchimento!D16="","-",Preenchimento!D16) -> - | F9: =IF(D9="P",10,IF(D9="F",0,"-")) -> - | G9: =IF(E9="P",10,IF(E9="F",0,"-")) -> - | H9: =IF(Preenchimento!$F$5="Online","Online",IF(Preenchimento!$F$5=1,F9,IF(Preenchimento!$F$5=2,(SUM(F9:G9)/2),"-"))) -> -
A10: 8 | B10: =IF(Preenchimento!B17="","-",Preenchimento!B17) -> - | C10: =IF(Preenchimento!D17="","-",Preenchimento!D17) -> - | F10: =IF(D10="P",10,IF(D10="F",0,"-")) -> - | G10: =IF(E10="P",10,IF(E10="F",0,"-")) -> - | H10: =IF(Preenchimento!$F$5="Online","Online",IF(Preenchimento!$F$5=1,F10,IF(Preenchimento!$F$5=2,(SUM(F10:G10)/2),"-"))) -> -
A11: 9 | B11: =IF(Preenchimento!B18="","-",Preenchimento!B18) -> - | C11: =IF(Preenchimento!D18="","-",Preenchimento!D18) -> - | F11: =IF(D11="P",10,IF(D11="F",0,"-")) -> - | G11: =IF(E11="P",10,IF(E11="F",0,"-")) -> - | H11: =IF(Preenchimento!$F$5="Online","Online",IF(Preenchimento!$F$5=1,F11,IF(Preenchimento!$F$5=2,(SUM(F11:G11)/2),"-"))) -> -
A12: 10 | B12: =IF(Preenchimento!B19="","-",Preenchimento!B19) -> - | C12: =IF(Preenchimento!D19="","-",Preenchimento!D19) -> - | F12: =IF(D12="P",10,IF(D12="F",0,"-")) -> - | G12: =IF(E12="P",10,IF(E12="F",0,"-")) -> - | H12: =IF(Preenchimento!$F$5="Online","Online",IF(Preenchimento!$F$5=1,F12,IF(Preenchimento!$F$5=2,(SUM(F12:G12)/2),"-"))) -> -
A13: 11 | B13: =IF(Preenchimento!B20="","-",Preenchimento!B20) -> - | C13: =IF(Preenchimento!D20="","-",Preenchimento!D20) -> - | F13: =IF(D13="P",10,IF(D13="F",0,"-")) -> - | G13: =IF(E13="P",10,IF(E13="F",0,"-")) -> - | H13: =IF(Preenchimento!$F$5="Online","Online",IF(Preenchimento!$F$5=1,F13,IF(Preenchimento!$F$5=2,(SUM(F13:G13)/2),"-"))) -> -
A14: 12 | B14: =IF(Preenchimento!B21="","-",Preenchimento!B21) -> - | C14: =IF(Preenchimento!D21="","-",Preenchimento!D21) -> - | F14: =IF(D14="P",10,IF(D14="F",0,"-")) -> - | G14: =IF(E14="P",10,IF(E14="F",0,"-")) -> - | H14: =IF(Preenchimento!$F$5="Online","Online",IF(Preenchimento!$F$5=1,F14,IF(Preenchimento!$F$5=2,(SUM(F14:G14)/2),"-"))) -> -
... A102: 100 | B102: =IF(Preenchimento!B109="","-",Preenchimento!B109) -> - | C102: =IF(Preenchimento!D109="","-",Preenchimento!D109) -> - | F102: =IF(D102="P",10,IF(D102="F",0,"-")) -> - | G102: =IF(E102="P",10,IF(E102="F",0,"-")) -> - | H102: =IF(Preenchimento!$F$5="Online","Online",IF(Preenchimento!$F$5=1,F102,IF(Preenchimento!$F$5=2,(SUM(F102:G102)/2),"-"))) -> -

Sheet Avaliações
E1: Avaliação do Diretor
D2: Presença | G2: Diplomacia e Respeito às regras | J2: Fidelidade à Função designada | O2: Contribuição | T2: Participação
B3: Nome | C3: Função | E3: 1ª Sessão | F3: 2ª Sessão | G3: 3ª Sessão | H3: 4ª Sessão | I3: 5ª Sessão | J3: 1ª Sessão | K3: 2ª Sessão | L3: 3ª Sessão | M3: 4ª Sessão | N3: 5ª Sessão | O3: 1ª Sessão | P3: 2ª Sessão | Q3: 3ª Sessão | R3: 4ª Sessão | S3: 5ª Sessão | T3: 1ª Sessão | U3: 2ª Sessão | V3: 3ª Sessão | W3: 4ª Sessão | X3: 5ª Sessão | Y3: Média
A4: 1 | B4: =IF(Preenchimento!B10="","-",Preenchimento!B10) -> - | C4: =IF(Preenchimento!D10="","-",Preenchimento!D10) -> - | D4: Falta | Y4: =if(or(D4="falta",D4=""),"-",if(D4="presente", IF(SUM(E4:X4)/20=0,"-",SUM(E4:X4)/20),"-")) -> -
A5: 2 | B5: =IF(Preenchimento!B11="","-",Preenchimento!B11) -> - | C5: =IF(Preenchimento!D11="","-",Preenchimento!D11) -> - | Y5: =if(or(D5="falta",D5=""),"-",if(D5="presente", IF(SUM(E5:X5)/20=0,"-",SUM(E5:X5)/20),"-")) -> -
A6: 3 | B6: =IF(Preenchimento!B12="","-",Preenchimento!B12) -> - | C6: =IF(Preenchimento!D12="","-",Preenchimento!D12) -> - | Y6: =if(or(D6="falta",D6=""),"-",if(D6="presente", IF(SUM(E6:X6)/20=0,"-",SUM(E6:X6)/20),"-")) -> -
A7: 4 | B7: =IF(Preenchimento!B13="","-",Preenchimento!B13) -> - | C7: =IF(Preenchimento!D13="","-",Preenchimento!D13) -> - | Y7: =if(or(D7="falta",D7=""),"-",if(D7="presente", IF(SUM(E7:X7)/20=0,"-",SUM(E7:X7)/20),"-")) -> -
A8: 5 | B8: =IF(Preenchimento!B14="","-",Preenchimento!B14) -> - | C8: =IF(Preenchimento!D14="","-",Preenchimento!D14) -> - | Y8: =if(or(D8="falta",D8=""),"-",if(D8="presente", IF(SUM(E8:X8)/20=0,"-",SUM(E8:X8)/20),"-")) -> -
A9: 6 | B9: =IF(Preenchimento!B15="","-",Preenchimento!B15) -> - | C9: =IF(Preenchimento!D15="","-",Preenchimento!D15) -> - | Y9: =if(or(D9="falta",D9=""),"-",if(D9="presente", IF(SUM(E9:X9)/20=0,"-",SUM(E9:X9)/20),"-")) -> -
A10: 7 | B10: =IF(Preenchimento!B16="","-",Preenchimento!B16) -> - | C10: =IF(Preenchimento!D16="","-",Preenchimento!D16) -> - | Y10: =if(or(D10="falta",D10=""),"-",if(D10="presente", IF(SUM(E10:X10)/20=0,"-",SUM(E10:X10)/20),"-")) -> -
A11: 8 | B11: =IF(Preenchimento!B17="","-",Preenchimento!B17) -> - | C11: =IF(Preenchimento!D17="","-",Preenchimento!D17) -> - | Y11: =if(or(D11="falta",D11=""),"-",if(D11="presente", IF(SUM(E11:X11)/20=0,"-",SUM(E11:X11)/20),"-")) -> -
A12: 9 | B12: =IF(Preenchimento!B18="","-",Preenchimento!B18) -> - | C12: =IF(Preenchimento!D18="","-",Preenchimento!D18) -> - | Y12: =if(or(D12="falta",D12=""),"-",if(D12="presente", IF(SUM(E12:X12)/20=0,"-",SUM(E12:X12)/20),"-")) -> -
A13: 10 | B13: =IF(Preenchimento!B19="","-",Preenchimento!B19) -> - | C13: =IF(Preenchimento!D19="","-",Preenchimento!D19) -> - | Y13: =if(or(D13="falta",D13=""),"-",if(D13="presente", IF(SUM(E13:X13)/20=0,"-",SUM(E13:X13)/20),"-")) -> -
A14: 11 | B14: =IF(Preenchimento!B20="","-",Preenchimento!B20) -> - | C14: =IF(Preenchimento!D20="","-",Preenchimento!D20) -> - | Y14: =if(or(D14="falta",D14=""),"-",if(D14="presente", IF(SUM(E14:X14)/20=0,"-",SUM(E14:X14)/20),"-")) -> -
A15: 12 | B15: =IF(Preenchimento!B21="","-",Preenchimento!B21) -> - | C15: =IF(Preenchimento!D21="","-",Preenchimento!D21) -> - | Y15: =if(or(D15="falta",D15=""),"-",if(D15="presente", IF(SUM(E15:X15)/20=0,"-",SUM(E15:X15)/20),"-")) -> -
A16: 13 | B16: =IF(Preenchimento!B22="","-",Preenchimento!B22) -> - | C16: =IF(Preenchimento!D22="","-",Preenchimento!D22) -> - | Y16: =if(or(D16="falta",D16=""),"-",if(D16="presente", IF(SUM(E16:X16)/20=0,"-",SUM(E16:X16)/20),"-")) -> -
... A53: 50 | B53: =IF(Preenchimento!B59="","-",Preenchimento!B59) -> - | C53: =IF(Preenchimento!D59="","-",Preenchimento!D59) -> - | Y53: =if(or(D53="falta",D53=""),"-",if(D53="presente", IF(SUM(E53:X53)/20=0,"-",SUM(E53:X53)/20),"-")) -> -
A54: 51 | B54: =IF(Preenchimento!B60="","-",Preenchimento!B60) -> - | C54: =IF(Preenchimento!D60="","-",Preenchimento!D60) -> - | Y54: =IF(OR(D54="falta",D54=""),"-",IF(D54="presente", IF(SUM(E54:X54)/20=0,"-",SUM(E54:X54)/20),"-")) -> -
A55: 52 | B55: =IF(Preenchimento!B61="","-",Preenchimento!B61) -> - | C55: =IF(Preenchimento!D61="","-",Preenchimento!D61) -> - | Y55: =IF(OR(D55="falta",D55=""),"-",IF(D55="presente", IF(SUM(E55:X55)/20=0,"-",SUM(E55:X55)/20),"-")) -> -
A56: 53 | B56: =IF(Preenchimento!B62="","-",Preenchimento!B62) -> - | C56: =IF(Preenchimento!D62="","-",Preenchimento!D62) -> - | Y56: =IF(OR(D56="falta",D56=""),"-",IF(D56="presente", IF(SUM(E56:X56)/20=0,"-",SUM(E56:X56)/20),"-")) -> -
A57: 54 | B57: =IF(Preenchimento!B63="","-",Preenchimento!B63) -> - | C57: =IF(Preenchimento!D63="","-",Preenchimento!D63) -> - | Y57: =IF(OR(D57="falta",D57=""),"-",IF(D57="presente", IF(SUM(E57:X57)/20=0,"-",SUM(E57:X57)/20),"-")) -> -
A58: 55 | B58: =IF(Preenchimento!B64="","-",Preenchimento!B64) -> - | C58: =IF(Preenchimento!D64="","-",Preenchimento!D64) -> - | Y58: =IF(OR(D58="falta",D58=""),"-",IF(D58="presente", IF(SUM(E58:X58)/20=0,"-",SUM(E58:X58)/20),"-")) -> -
A59: 56 | B59: =IF(Preenchimento!B65="","-",Preenchimento!B65) -> - | C59: =IF(Preenchimento!D65="","-",Preenchimento!D65) -> - | Y59: =IF(OR(D59="falta",D59=""),"-",IF(D59="presente", IF(SUM(E59:X59)/20=0,"-",SUM(E59:X59)/20),"-")) -> -
A60: 57 | B60: =IF(Preenchimento!B66="","-",Preenchimento!B66) -> - | C60: =IF(Preenchimento!D66="","-",Preenchimento!D66) -> - | Y60: =IF(OR(D60="falta",D60=""),"-",IF(D60="presente", IF(SUM(E60:X60)/20=0,"-",SUM(E60:X60)/20),"-")) -> -
A61: 58 | B61: =IF(Preenchimento!B67="","-",Preenchimento!B67) -> - | C61: =IF(Preenchimento!D67="","-",Preenchimento!D67) -> - | Y61: =IF(OR(D61="falta",D61=""),"-",IF(D61="presente", IF(SUM(E61:X61)/20=0,"-",SUM(E61:X61)/20),"-")) -> -
A62: 59 | B62: =IF(Preenchimento!B68="","-",Preenchimento!B68) -> - | C62: =IF(Preenchimento!D68="","-",Preenchimento!D68) -> - | Y62: =IF(OR(D62="falta",D62=""),"-",IF(D62="presente", IF(SUM(E62:X62)/20=0,"-",SUM(E62:X62)/20),"-")) -> -
A63: 60 | B63: =IF(Preenchimento!B69="","-",Preenchimento!B69) -> - | C63: =IF(Preenchimento!D69="","-",Preenchimento!D69) -> - | Y63: =IF(OR(D63="falta",D63=""),"-",IF(D63="presente", IF(SUM(E63:X63)/20=0,"-",SUM(E63:X63)/20),"-")) -> -
A64: 61 | B64: =IF(Preenchimento!B70="","-",Preenchimento!B70) -> - | C64: =IF(Preenchimento!D70="","-",Preenchimento!D70) -> - | Y64: =IF(OR(D64="falta",D64=""),"-",IF(D64="presente", IF(SUM(E64:X64)/20=0,"-",SUM(E64:X64)/20),"-")) -> -
A65: 62 | B65: =IF(Preenchimento!B71="","-",Preenchimento!B71) -> - | C65: =IF(Preenchimento!D71="","-",Preenchimento!D71) -> - | Y65: =IF(OR(D65="falta",D65=""),"-",IF(D65="presente", IF(SUM(E65:X65)/20=0,"-",SUM(E65:X65)/20),"-")) -> -
... A103: 100 | B103: =IF(Preenchimento!B109="","-",Preenchimento!B109) -> - | C103: =IF(Preenchimento!D109="","-",Preenchimento!D109) -> - | Y103: =IF(OR(D103="falta",D103=""),"-",IF(D103="presente", IF(SUM(E103:X103)/20=0,"-",SUM(E103:X103)/20),"-")) -> -

Sheet DPO
B1: Avaliação Escrita
B2: Nome | D2: Função | E2: Ortografia | F2: Conteúdo | G2: Apresentação | H2: Respeito ao prazo | I2: Média
A3: 1 | B3: =IF(Preenchimento!B10="","-",Preenchimento!B10) -> - | C3: ='Avaliações'!D4 -> Falta | D3: =IF(Preenchimento!D10="","-",Preenchimento!D10) -> - | I3: =if(or('Avaliações'!D4="falta",'Avaliações'!D4=""),"-",if('Avaliações'!D4="presente", IF(SUM(E3*0.25,F3*0.5,G3*0.125,H3*0.125)= 0,"-",SUM(E3*0.25,F3*0.5,G3*0.125,H3*0.125)))) -> -
A4: 2 | B4: =IF(Preenchimento!B11="","-",Preenchimento!B11) -> - | C4: ='Avaliações'!D5 | D4: =IF(Preenchimento!D11="","-",Preenchimento!D11) -> - | I4: =if(or('Avaliações'!D5="falta",'Avaliações'!D5=""),"-",if('Avaliações'!D5="presente", IF(SUM(E4*0.25,F4*0.5,G4*0.125,H4*0.125)=0,"-",SUM(E4*0.25,F4*0.5,G4*0.125,H4*0.125)))) -> -
A5: 3 | B5: =IF(Preenchimento!B12="","-",Preenchimento!B12) -> - | C5: ='Avaliações'!D6 | D5: =IF(Preenchimento!D12="","-",Preenchimento!D12) -> - | I5: =if(or('Avaliações'!D6="falta",'Avaliações'!D6=""),"-",if('Avaliações'!D6="presente", IF(SUM(E5*0.25,F5*0.5,G5*0.125,H5*0.125)=0,"-",SUM(E5*0.25,F5*0.5,G5*0.125,H5*0.125)))) -> -
A6: 4 | B6: =IF(Preenchimento!B13="","-",Preenchimento!B13) -> - | C6: ='Avaliações'!D7 | D6: =IF(Preenchimento!D13="","-",Preenchimento!D13) -> - | I6: =if(or('Avaliações'!D7="falta",'Avaliações'!D7=""),"-",if('Avaliações'!D7="presente", IF(SUM(E6*0.25,F6*0.5,G6*0.125,H6*0.125)=0,"-",SUM(E6*0.25,F6*0.5,G6*0.125,H6*0.125)))) -> -
A7: 5 | B7: =IF(Preenchimento!B14="","-",Preenchimento!B14) -> - | C7: ='Avaliações'!D8 | D7: =IF(Preenchimento!D14="","-",Preenchimento!D14) -> - | I7: =if(or('Avaliações'!D8="falta",'Avaliações'!D8=""),"-",if('Avaliações'!D8="presente", IF(SUM(E7*0.25,F7*0.5,G7*0.125,H7*0.125)=0,"-",SUM(E7*0.25,F7*0.5,G7*0.125,H7*0.125)))) -> -
A8: 6 | B8: =IF(Preenchimento!B15="","-",Preenchimento!B15) -> - | C8: ='Avaliações'!D9 | D8: =IF(Preenchimento!D15="","-",Preenchimento!D15) -> - | I8: =if(or('Avaliações'!D9="falta",'Avaliações'!D9=""),"-",if('Avaliações'!D9="presente", IF(SUM(E8*0.25,F8*0.5,G8*0.125,H8*0.125)=0,"-",SUM(E8*0.25,F8*0.5,G8*0.125,H8*0.125)))) -> -
A9: 7 | B9: =IF(Preenchimento!B16="","-",Preenchimento!B16) -> - | C9: ='Avaliações'!D10 | D9: =IF(Preenchimento!D16="","-",Preenchimento!D16) -> - | I9: =if(or('Avaliações'!D10="falta",'Avaliações'!D10=""),"-",if('Avaliações'!D10="presente", IF(SUM(E9*0.25,F9*0.5,G9*0.125,H9*0.125)=0,"-",SUM(E9*0.25,F9*0.5,G9*0.125,H9*0.125)))) -> -
A10: 8 | B10: =IF(Preenchimento!B17="","-",Preenchimento!B17) -> - | C10: ='Avaliações'!D11 | D10: =IF(Preenchimento!D17="","-",Preenchimento!D17) -> - | I10: =if(or('Avaliações'!D11="falta",'Avaliações'!D11=""),"-",if('Avaliações'!D11="presente", IF(SUM(E10*0.25,F10*0.5,G10*0.125,H10*0.125)=0,"-",SUM(E10*0.25,F10*0.5,G10*0.125,H10*0.125)))) -> -
A11: 9 | B11: =IF(Preenchimento!B18="","-",Preenchimento!B18) -> - | C11: ='Avaliações'!D12 | D11: =IF(Preenchimento!D18="","-",Preenchimento!D18) -> - | I11: =if(or('Avaliações'!D12="falta",'Avaliações'!D12=""),"-",if('Avaliações'!D12="presente", IF(SUM(E11*0.25,F11*0.5,G11*0.125,H11*0.125)=0,"-",SUM(E11*0.25,F11*0.5,G11*0.125,H11*0.125)))) -> -
A12: 10 | B12: =IF(Preenchimento!B19="","-",Preenchimento!B19) -> - | C12: ='Avaliações'!D13 | D12: =IF(Preenchimento!D19="","-",Preenchimento!D19) -> - | I12: =if(or('Avaliações'!D13="falta",'Avaliações'!D13=""),"-",if('Avaliações'!D13="presente", IF(SUM(E12*0.25,F12*0.5,G12*0.125,H12*0.125)=0,"-",SUM(E12*0.25,F12*0.5,G12*0.125,H12*0.125)))) -> -
A13: 11 | B13: =IF(Preenchimento!B20="","-",Preenchimento!B20) -> - | C13: ='Avaliações'!D14 | D13: =IF(Preenchimento!D20="","-",Preenchimento!D20) -> - | I13: =if(or('Avaliações'!D14="falta",'Avaliações'!D14=""),"-",if('Avaliações'!D14="presente", IF(SUM(E13*0.25,F13*0.5,G13*0.125,H13*0.125)=0,"-",SUM(E13*0.25,F13*0.5,G13*0.125,H13*0.125)))) -> -
A14: 12 | B14: =IF(Preenchimento!B21="","-",Preenchimento!B21) -> - | C14: ='Avaliações'!D15 | D14: =IF(Preenchimento!D21="","-",Preenchimento!D21) -> - | I14: =if(or('Avaliações'!D15="falta",'Avaliações'!D15=""),"-",if('Avaliações'!D15="presente", IF(SUM(E14*0.25,F14*0.5,G14*0.125,H14*0.125)=0,"-",SUM(E14*0.25,F14*0.5,G14*0.125,H14*0.125)))) -> -
A15: 13 | B15: =IF(Preenchimento!B22="","-",Preenchimento!B22) -> - | C15: ='Avaliações'!D16 | D15: =IF(Preenchimento!D22="","-",Preenchimento!D22) -> - | I15: =if(or('Avaliações'!D16="falta",'Avaliações'!D16=""),"-",if('Avaliações'!D16="presente", IF(SUM(E15*0.25,F15*0.5,G15*0.125,H15*0.125)=0,"-",SUM(E15*0.25,F15*0.5,G15*0.125,H15*0.125)))) -> -
... A52: 50 | B52: =IF(Preenchimento!B59="","-",Preenchimento!B59) -> - | C52: ='Avaliações'!D53 | D52: =IF(Preenchimento!D59="","-",Preenchimento!D59) -> - | I52: =if(or('Avaliações'!D53="falta",'Avaliações'!D53=""),"-",if('Avaliações'!D53="presente", IF(SUM(E52*0.25,F52*0.5,G52*0.125,H52*0.125)=0,"-",SUM(E52*0.25,F52*0.5,G52*0.125,H52*0.125)))) -> -
A53: 51 | B53: =IF(Preenchimento!B60="","-",Preenchimento!B60) -> - | C53: ='Avaliações'!D54 | D53: =IF(Preenchimento!D60="","-",Preenchimento!D60) -> - | I53: =IF(OR('Avaliações'!D54="falta",'Avaliações'!D54=""),"-",IF('Avaliações'!D54="presente", IF(SUM(E53*0.25,F53*0.5,G53*0.125,H53*0.125)=0,"-",SUM(E53*0.25,F53*0.5,G53*0.125,H53*0.125)))) -> -
A54: 52 | B54: =IF(Preenchimento!B61="","-",Preenchimento!B61) -> - | C54: ='Avaliações'!D55 | D54: =IF(Preenchimento!D61="","-",Preenchimento!D61) -> - | I54: =IF(OR('Avaliações'!D55="falta",'Avaliações'!D55=""),"-",IF('Avaliações'!D55="presente", IF(SUM(E54*0.25,F54*0.5,G54*0.125,H54*0.125)=0,"-",SUM(E54*0.25,F54*0.5,G54*0.125,H54*0.125)))) -> -
A55: 53 | B55: =IF(Preenchimento!B62="","-",Preenchimento!B62) -> - | C55: ='Avaliações'!D56 | D55: =IF(Preenchimento!D62="","-",Preenchimento!D62) -> - | I55: =IF(OR('Avaliações'!D56="falta",'Avaliações'!D56=""),"-",IF('Avaliações'!D56="presente", IF(SUM(E55*0.25,F55*0.5,G55*0.125,H55*0.125)=0,"-",SUM(E55*0.25,F55*0.5,G55*0.125,H55*0.125)))) -> -
A56: 54 | B56: =IF(Preenchimento!B63="","-",Preenchimento!B63) -> - | C56: ='Avaliações'!D57 | D56: =IF(Preenchimento!D63="","-",Preenchimento!D63) -> - | I56: =IF(OR('Avaliações'!D57="falta",'Avaliações'!D57=""),"-",IF('Avaliações'!D57="presente", IF(SUM(E56*0.25,F56*0.5,G56*0.125,H56*0.125)=0,"-",SUM(E56*0.25,F56*0.5,G56*0.125,H56*0.125)))) -> -
A57: 55 | B57: =IF(Preenchimento!B64="","-",Preenchimento!B64) -> - | C57: ='Avaliações'!D58 | D57: =IF(Preenchimento!D64="","-",Preenchimento!D64) -> - | I57: =IF(OR('Avaliações'!D58="falta",'Avaliações'!D58=""),"-",IF('Avaliações'!D58="presente", IF(SUM(E57*0.25,F57*0.5,G57*0.125,H57*0.125)=0,"-",SUM(E57*0.25,F57*0.5,G57*0.125,H57*0.125)))) -> -
A58: 56 | B58: =IF(Preenchimento!B65="","-",Preenchimento!B65) -> - | C58: ='Avaliações'!D59 | D58: =IF(Preenchimento!D65="","-",Preenchimento!D65) -> - | I58: =IF(OR('Avaliações'!D59="falta",'Avaliações'!D59=""),"-",IF('Avaliações'!D59="presente", IF(SUM(E58*0.25,F58*0.5,G58*0.125,H58*0.125)=0,"-",SUM(E58*0.25,F58*0.5,G58*0.125,H58*0.125)))) -> -
A59: 57 | B59: =IF(Preenchimento!B66="","-",Preenchimento!B66) -> - | C59: ='Avaliações'!D60 | D59: =IF(Preenchimento!D66="","-",Preenchimento!D66) -> - | I59: =IF(OR('Avaliações'!D60="falta",'Avaliações'!D60=""),"-",IF('Avaliações'!D60="presente", IF(SUM(E59*0.25,F59*0.5,G59*0.125,H59*0.125)=0,"-",SUM(E59*0.25,F59*0.5,G59*0.125,H59*0.125)))) -> -
A60: 58 | B60: =IF(Preenchimento!B67="","-",Preenchimento!B67) -> - | C60: ='Avaliações'!D61 | D60: =IF(Preenchimento!D67="","-",Preenchimento!D67) -> - | I60: =IF(OR('Avaliações'!D61="falta",'Avaliações'!D61=""),"-",IF('Avaliações'!D61="presente", IF(SUM(E60*0.25,F60*0.5,G60*0.125,H60*0.125)=0,"-",SUM(E60*0.25,F60*0.5,G60*0.125,H60*0.125)))) -> -
A61: 59 | B61: =IF(Preenchimento!B68="","-",Preenchimento!B68) -> - | C61: ='Avaliações'!D62 | D61: =IF(Preenchimento!D68="","-",Preenchimento!D68) -> - | I61: =IF(OR('Avaliações'!D62="falta",'Avaliações'!D62=""),"-",IF('Avaliações'!D62="presente", IF(SUM(E61*0.25,F61*0.5,G61*0.125,H61*0.125)=0,"-",SUM(E61*0.25,F61*0.5,G61*0.125,H61*0.125)))) -> -
A62: 60 | B62: =IF(Preenchimento!B69="","-",Preenchimento!B69) -> - | C62: ='Avaliações'!D63 | D62: =IF(Preenchimento!D69="","-",Preenchimento!D69) -> - | I62: =IF(OR('Avaliações'!D63="falta",'Avaliações'!D63=""),"-",IF('Avaliações'!D63="presente", IF(SUM(E62*0.25,F62*0.5,G62*0.125,H62*0.125)=0,"-",SUM(E62*0.25,F62*0.5,G62*0.125,H62*0.125)))) -> -
A63: 61 | B63: =IF(Preenchimento!B70="","-",Preenchimento!B70) -> - | C63: ='Avaliações'!D64 | D63: =IF(Preenchimento!D70="","-",Preenchimento!D70) -> - | I63: =IF(OR('Avaliações'!D64="falta",'Avaliações'!D64=""),"-",IF('Avaliações'!D64="presente", IF(SUM(E63*0.25,F63*0.5,G63*0.125,H63*0.125)=0,"-",SUM(E63*0.25,F63*0.5,G63*0.125,H63*0.125)))) -> -
A64: 62 | B64: =IF(Preenchimento!B71="","-",Preenchimento!B71) -> - | C64: ='Avaliações'!D65 | D64: =IF(Preenchimento!D71="","-",Preenchimento!D71) -> - | I64: =IF(OR('Avaliações'!D65="falta",'Avaliações'!D65=""),"-",IF('Avaliações'!D65="presente", IF(SUM(E64*0.25,F64*0.5,G64*0.125,H64*0.125)=0,"-",SUM(E64*0.25,F64*0.5,G64*0.125,H64*0.125)))) -> -
... A102: 100 | B102: =IF(Preenchimento!B109="","-",Preenchimento!B109) -> - | C102: ='Avaliações'!D103 | D102: =IF(Preenchimento!D109="","-",Preenchimento!D109) -> - | I102: =IF(OR('Avaliações'!D103="falta",'Avaliações'!D103=""),"-",IF('Avaliações'!D103="presente", IF(SUM(E102*0.25,F102*0.5,G102*0.125,H102*0.125)=0,"-",SUM(E102*0.25,F102*0.5,G102*0.125,H102*0.125)))) -> -

Sheet NC
A1: Tipo de Avaliação | D1: =Preenchimento!$F$7 | F1: Noite Cultural | N1: AUTOPREENCHIMENTO DE NOTAS - NOITE CULTURAL
F2: Apresentação de Palco | I2: Estande | P2: Apresentação de Palco | S2: Estande
B3: Nome | D3: Função | E3: Grupo | F3: Tempo | G3: Originalidade | H3: Caracterização | I3: Tempo | J3: Originalidade | K3: Conteúdo | L3: Caracterização | M3: Média | O3: Grupo | P3: Tempo | Q3: Originalidade | R3: Caracterização | S3: Tempo | T3: Originalidade | U3: Conteúdo | V3: Caracterização
A4: 1 | B4: =IF(Preenchimento!B10="","-",Preenchimento!B10) -> - | C4: ='Avaliações'!D4 -> Falta | D4: =IF(Preenchimento!D10="","-",Preenchimento!D10) -> - | E4: =IF(Preenchimento!E10="","",Preenchimento!E10) | F4: =IFERROR(VLOOKUP($E4,$O$4:$V$29,2),"-") -> - | G4: =IFERROR(VLOOKUP($E4,$O$4:$V$29,3),"-") -> - | H4: =IFERROR(VLOOKUP($E4,$O$4:$V$29,4),"-") -> - | I4: =IFERROR(VLOOKUP($E4,$O$4:$V$29,5),"-") -> - | J4: =IFERROR(VLOOKUP($E4,$O$4:$V$29,6),"-") -> - | K4: =IFERROR(VLOOKUP($E4,$O$4:$V$29,7),"-") -> - | L4: =IFERROR(VLOOKUP($E4,$O$4:$V$29,8),"-") -> - | M4: =if(or('Avaliações'!D4="falta",'Avaliações'!D4=""),"-",if('Avaliações'!D4="presente", IF(IF(AND(F4="",G4="",H4=""),SUM(I4:L4)/4,SUM(F4:L4)/7)=0,"-",IF(AND(F4="",G4="",H4=""),SUM(I4:L4)/4,SUM(F4:L4)/7)))) -> - | O4: A
A5: 2 | B5: =IF(Preenchimento!B11="","-",Preenchimento!B11) -> - | C5: ='Avaliações'!D5 | D5: =IF(Preenchimento!D11="","-",Preenchimento!D11) -> - | E5: =IF(Preenchimento!E11="","",Preenchimento!E11) | F5: =IFERROR(VLOOKUP($E5,$O$4:$V$29,2),"-") -> - | G5: =IFERROR(VLOOKUP($E5,$O$4:$V$29,3),"-") -> - | H5: =IFERROR(VLOOKUP($E5,$O$4:$V$29,4),"-") -> - | I5: =IFERROR(VLOOKUP($E5,$O$4:$V$29,5),"-") -> - | J5: =IFERROR(VLOOKUP($E5,$O$4:$V$29,6),"-") -> - | K5: =IFERROR(VLOOKUP($E5,$O$4:$V$29,7),"-") -> - | L5: =IFERROR(VLOOKUP($E5,$O$4:$V$29,8),"-") -> - | M5: =if(or('Avaliações'!D5="falta",'Avaliações'!D5=""),"-",if('Avaliações'!D5="presente", IF(IF(AND(F5="",G5="",H5=""),SUM(I5:L5)/4,SUM(F5:L5)/7)=0,"-",IF(AND(F5="",G5="",H5=""),SUM(I5:L5)/4,SUM(F5:L5)/7)))) -> - | O5: B
A6: 3 | B6: =IF(Preenchimento!B12="","-",Preenchimento!B12) -> - | C6: ='Avaliações'!D6 | D6: =IF(Preenchimento!D12="","-",Preenchimento!D12) -> - | E6: =IF(Preenchimento!E12="","",Preenchimento!E12) | F6: =IFERROR(VLOOKUP($E6,$O$4:$V$29,2),"-") -> - | G6: =IFERROR(VLOOKUP($E6,$O$4:$V$29,3),"-") -> - | H6: =IFERROR(VLOOKUP($E6,$O$4:$V$29,4),"-") -> - | I6: =IFERROR(VLOOKUP($E6,$O$4:$V$29,5),"-") -> - | J6: =IFERROR(VLOOKUP($E6,$O$4:$V$29,6),"-") -> - | K6: =IFERROR(VLOOKUP($E6,$O$4:$V$29,7),"-") -> - | L6: =IFERROR(VLOOKUP($E6,$O$4:$V$29,8),"-") -> - | M6: =if(or('Avaliações'!D6="falta",'Avaliações'!D6=""),"-",if('Avaliações'!D6="presente", IF(IF(AND(F6="",G6="",H6=""),SUM(I6:L6)/4,SUM(F6:L6)/7)=0,"-",IF(AND(F6="",G6="",H6=""),SUM(I6:L6)/4,SUM(F6:L6)/7)))) -> - | O6: C
A7: 4 | B7: =IF(Preenchimento!B13="","-",Preenchimento!B13) -> - | C7: ='Avaliações'!D7 | D7: =IF(Preenchimento!D13="","-",Preenchimento!D13) -> - | E7: =IF(Preenchimento!E13="","",Preenchimento!E13) | F7: =IFERROR(VLOOKUP($E7,$O$4:$V$29,2),"-") -> - | G7: =IFERROR(VLOOKUP($E7,$O$4:$V$29,3),"-") -> - | H7: =IFERROR(VLOOKUP($E7,$O$4:$V$29,4),"-") -> - | I7: =IFERROR(VLOOKUP($E7,$O$4:$V$29,5),"-") -> - | J7: =IFERROR(VLOOKUP($E7,$O$4:$V$29,6),"-") -> - | K7: =IFERROR(VLOOKUP($E7,$O$4:$V$29,7),"-") -> - | L7: =IFERROR(VLOOKUP($E7,$O$4:$V$29,8),"-") -> - | M7: =if(or('Avaliações'!D7="falta",'Avaliações'!D7=""),"-",if('Avaliações'!D7="presente", IF(IF(AND(F7="",G7="",H7=""),SUM(I7:L7)/4,SUM(F7:L7)/7)=0,"-",IF(AND(F7="",G7="",H7=""),SUM(I7:L7)/4,SUM(F7:L7)/7)))) -> - | O7: D
A8: 5 | B8: =IF(Preenchimento!B14="","-",Preenchimento!B14) -> - | C8: ='Avaliações'!D8 | D8: =IF(Preenchimento!D14="","-",Preenchimento!D14) -> - | E8: =IF(Preenchimento!E14="","",Preenchimento!E14) | F8: =IFERROR(VLOOKUP($E8,$O$4:$V$29,2),"-") -> - | G8: =IFERROR(VLOOKUP($E8,$O$4:$V$29,3),"-") -> - | H8: =IFERROR(VLOOKUP($E8,$O$4:$V$29,4),"-") -> - | I8: =IFERROR(VLOOKUP($E8,$O$4:$V$29,5),"-") -> - | J8: =IFERROR(VLOOKUP($E8,$O$4:$V$29,6),"-") -> - | K8: =IFERROR(VLOOKUP($E8,$O$4:$V$29,7),"-") -> - | L8: =IFERROR(VLOOKUP($E8,$O$4:$V$29,8),"-") -> - | M8: =if(or('Avaliações'!D8="falta",'Avaliações'!D8=""),"-",if('Avaliações'!D8="presente", IF(IF(AND(F8="",G8="",H8=""),SUM(I8:L8)/4,SUM(F8:L8)/7)=0,"-",IF(AND(F8="",G8="",H8=""),SUM(I8:L8)/4,SUM(F8:L8)/7)))) -> - | O8: E
A9: 6 | B9: =IF(Preenchimento!B15="","-",Preenchimento!B15) -> - | C9: ='Avaliações'!D9 | D9: =IF(Preenchimento!D15="","-",Preenchimento!D15) -> - | E9: =IF(Preenchimento!E15="","",Preenchimento!E15) | F9: =IFERROR(VLOOKUP($E9,$O$4:$V$29,2),"-") -> - | G9: =IFERROR(VLOOKUP($E9,$O$4:$V$29,3),"-") -> - | H9: =IFERROR(VLOOKUP($E9,$O$4:$V$29,4),"-") -> - | I9: =IFERROR(VLOOKUP($E9,$O$4:$V$29,5),"-") -> - | J9: =IFERROR(VLOOKUP($E9,$O$4:$V$29,6),"-") -> - | K9: =IFERROR(VLOOKUP($E9,$O$4:$V$29,7),"-") -> - | L9: =IFERROR(VLOOKUP($E9,$O$4:$V$29,8),"-") -> - | M9: =if(or('Avaliações'!D9="falta",'Avaliações'!D9=""),"-",if('Avaliações'!D9="presente", IF(IF(AND(F9="",G9="",H9=""),SUM(I9:L9)/4,SUM(F9:L9)/7)=0,"-",IF(AND(F9="",G9="",H9=""),SUM(I9:L9)/4,SUM(F9:L9)/7)))) -> - | O9: F
A10: 7 | B10: =IF(Preenchimento!B16="","-",Preenchimento!B16) -> - | C10: ='Avaliações'!D10 | D10: =IF(Preenchimento!D16="","-",Preenchimento!D16) -> - | E10: =IF(Preenchimento!E16="","",Preenchimento!E16) | F10: =IFERROR(VLOOKUP($E10,$O$4:$V$29,2),"-") -> - | G10: =IFERROR(VLOOKUP($E10,$O$4:$V$29,3),"-") -> - | H10: =IFERROR(VLOOKUP($E10,$O$4:$V$29,4),"-") -> - | I10: =IFERROR(VLOOKUP($E10,$O$4:$V$29,5),"-") -> - | J10: =IFERROR(VLOOKUP($E10,$O$4:$V$29,6),"-") -> - | K10: =IFERROR(VLOOKUP($E10,$O$4:$V$29,7),"-") -> - | L10: =IFERROR(VLOOKUP($E10,$O$4:$V$29,8),"-") -> - | M10: =if(or('Avaliações'!D10="falta",'Avaliações'!D10=""),"-",if('Avaliações'!D10="presente", IF(IF(AND(F10="",G10="",H10=""),SUM(I10:L10)/4,SUM(F10:L10)/7)=0,"-",IF(AND(F10="",G10="",H10=""),SUM(I10:L10)/4,SUM(F10:L10)/7)))) -> - | O10: G
A11: 8 | B11: =IF(Preenchimento!B17="","-",Preenchimento!B17) -> - | C11: ='Avaliações'!D11 | D11: =IF(Preenchimento!D17="","-",Preenchimento!D17) -> - | E11: =IF(Preenchimento!E17="","",Preenchimento!E17) | F11: =IFERROR(VLOOKUP($E11,$O$4:$V$29,2),"-") -> - | G11: =IFERROR(VLOOKUP($E11,$O$4:$V$29,3),"-") -> - | H11: =IFERROR(VLOOKUP($E11,$O$4:$V$29,4),"-") -> - | I11: =IFERROR(VLOOKUP($E11,$O$4:$V$29,5),"-") -> - | J11: =IFERROR(VLOOKUP($E11,$O$4:$V$29,6),"-") -> - | K11: =IFERROR(VLOOKUP($E11,$O$4:$V$29,7),"-") -> - | L11: =IFERROR(VLOOKUP($E11,$O$4:$V$29,8),"-") -> - | M11: =if(or('Avaliações'!D11="falta",'Avaliações'!D11=""),"-",if('Avaliações'!D11="presente", IF(IF(AND(F11="",G11="",H11=""),SUM(I11:L11)/4,SUM(F11:L11)/7)=0,"-",IF(AND(F11="",G11="",H11=""),SUM(I11:L11)/4,SUM(F11:L11)/7)))) -> - | O11: H
A12: 9 | B12: =IF(Preenchimento!B18="","-",Preenchimento!B18) -> - | C12: ='Avaliações'!D12 | D12: =IF(Preenchimento!D18="","-",Preenchimento!D18) -> - | E12: =IF(Preenchimento!E18="","",Preenchimento!E18) | F12: =IFERROR(VLOOKUP($E12,$O$4:$V$29,2),"-") -> - | G12: =IFERROR(VLOOKUP($E12,$O$4:$V$29,3),"-") -> - | H12: =IFERROR(VLOOKUP($E12,$O$4:$V$29,4),"-") -> - | I12: =IFERROR(VLOOKUP($E12,$O$4:$V$29,5),"-") -> - | J12: =IFERROR(VLOOKUP($E12,$O$4:$V$29,6),"-") -> - | K12: =IFERROR(VLOOKUP($E12,$O$4:$V$29,7),"-") -> - | L12: =IFERROR(VLOOKUP($E12,$O$4:$V$29,8),"-") -> - | M12: =if(or('Avaliações'!D12="falta",'Avaliações'!D12=""),"-",if('Avaliações'!D12="presente", IF(IF(AND(F12="",G12="",H12=""),SUM(I12:L12)/4,SUM(F12:L12)/7)=0,"-",IF(AND(F12="",G12="",H12=""),SUM(I12:L12)/4,SUM(F12:L12)/7)))) -> - | O12: I
A13: 10 | B13: =IF(Preenchimento!B19="","-",Preenchimento!B19) -> - | C13: ='Avaliações'!D13 | D13: =IF(Preenchimento!D19="","-",Preenchimento!D19) -> - | E13: =IF(Preenchimento!E19="","",Preenchimento!E19) | F13: =IFERROR(VLOOKUP($E13,$O$4:$V$29,2),"-") -> - | G13: =IFERROR(VLOOKUP($E13,$O$4:$V$29,3),"-") -> - | H13: =IFERROR(VLOOKUP($E13,$O$4:$V$29,4),"-") -> - | I13: =IFERROR(VLOOKUP($E13,$O$4:$V$29,5),"-") -> - | J13: =IFERROR(VLOOKUP($E13,$O$4:$V$29,6),"-") -> - | K13: =IFERROR(VLOOKUP($E13,$O$4:$V$29,7),"-") -> - | L13: =IFERROR(VLOOKUP($E13,$O$4:$V$29,8),"-") -> - | M13: =if(or('Avaliações'!D13="falta",'Avaliações'!D13=""),"-",if('Avaliações'!D13="presente", IF(IF(AND(F13="",G13="",H13=""),SUM(I13:L13)/4,SUM(F13:L13)/7)=0,"-",IF(AND(F13="",G13="",H13=""),SUM(I13:L13)/4,SUM(F13:L13)/7)))) -> - | O13: J
A14: 11 | B14: =IF(Preenchimento!B20="","-",Preenchimento!B20) -> - | C14: ='Avaliações'!D14 | D14: =IF(Preenchimento!D20="","-",Preenchimento!D20) -> - | E14: =IF(Preenchimento!E20="","",Preenchimento!E20) | F14: =IFERROR(VLOOKUP($E14,$O$4:$V$29,2),"-") -> - | G14: =IFERROR(VLOOKUP($E14,$O$4:$V$29,3),"-") -> - | H14: =IFERROR(VLOOKUP($E14,$O$4:$V$29,4),"-") -> - | I14: =IFERROR(VLOOKUP($E14,$O$4:$V$29,5),"-") -> - | J14: =IFERROR(VLOOKUP($E14,$O$4:$V$29,6),"-") -> - | K14: =IFERROR(VLOOKUP($E14,$O$4:$V$29,7),"-") -> - | L14: =IFERROR(VLOOKUP($E14,$O$4:$V$29,8),"-") -> - | M14: =if(or('Avaliações'!D14="falta",'Avaliações'!D14=""),"-",if('Avaliações'!D14="presente", IF(IF(AND(F14="",G14="",H14=""),SUM(I14:L14)/4,SUM(F14:L14)/7)=0,"-",IF(AND(F14="",G14="",H14=""),SUM(I14:L14)/4,SUM(F14:L14)/7)))) -> - | O14: K
A15: 12 | B15: =IF(Preenchimento!B21="","-",Preenchimento!B21) -> - | C15: ='Avaliações'!D15 | D15: =IF(Preenchimento!D21="","-",Preenchimento!D21) -> - | E15: =IF(Preenchimento!E21="","",Preenchimento!E21) | F15: =IFERROR(VLOOKUP($E15,$O$4:$V$29,2),"-") -> - | G15: =IFERROR(VLOOKUP($E15,$O$4:$V$29,3),"-") -> - | H15: =IFERROR(VLOOKUP($E15,$O$4:$V$29,4),"-") -> - | I15: =IFERROR(VLOOKUP($E15,$O$4:$V$29,5),"-") -> - | J15: =IFERROR(VLOOKUP($E15,$O$4:$V$29,6),"-") -> - | K15: =IFERROR(VLOOKUP($E15,$O$4:$V$29,7),"-") -> - | L15: =IFERROR(VLOOKUP($E15,$O$4:$V$29,8),"-") -> - | M15: =if(or('Avaliações'!D15="falta",'Avaliações'!D15=""),"-",if('Avaliações'!D15="presente", IF(IF(AND(F15="",G15="",H15=""),SUM(I15:L15)/4,SUM(F15:L15)/7)=0,"-",IF(AND(F15="",G15="",H15=""),SUM(I15:L15)/4,SUM(F15:L15)/7)))) -> - | O15: L
... A29: 26 | B29: =IF(Preenchimento!B35="","-",Preenchimento!B35) -> - | C29: ='Avaliações'!D29 | D29: =IF(Preenchimento!D35="","-",Preenchimento!D35) -> - | E29: =IF(Preenchimento!E35="","",Preenchimento!E35) | F29: =IFERROR(VLOOKUP($E29,$O$4:$V$29,2),"-") -> - | G29: =IFERROR(VLOOKUP($E29,$O$4:$V$29,3),"-") -> - | H29: =IFERROR(VLOOKUP($E29,$O$4:$V$29,4),"-") -> - | I29: =IFERROR(VLOOKUP($E29,$O$4:$V$29,5),"-") -> - | J29: =IFERROR(VLOOKUP($E29,$O$4:$V$29,6),"-") -> - | K29: =IFERROR(VLOOKUP($E29,$O$4:$V$29,7),"-") -> - | L29: =IFERROR(VLOOKUP($E29,$O$4:$V$29,8),"-") -> - | M29: =if(or('Avaliações'!D29="falta",'Avaliações'!D29=""),"-",if('Avaliações'!D29="presente", IF(IF(AND(F29="",G29="",H29=""),SUM(I29:L29)/4,SUM(F29:L29)/7)=0,"-",IF(AND(F29="",G29="",H29=""),SUM(I29:L29)/4,SUM(F29:L29)/7)))) -> - | O29: Z
A30: 27 | B30: =IF(Preenchimento!B36="","-",Preenchimento!B36) -> - | C30: ='Avaliações'!D30 | D30: =IF(Preenchimento!D36="","-",Preenchimento!D36) -> - | E30: =IF(Preenchimento!E36="","",Preenchimento!E36) | F30: =IFERROR(VLOOKUP($E30,$O$4:$V$29,2),"-") -> - | G30: =IFERROR(VLOOKUP($E30,$O$4:$V$29,3),"-") -> - | H30: =IFERROR(VLOOKUP($E30,$O$4:$V$29,4),"-") -> - | I30: =IFERROR(VLOOKUP($E30,$O$4:$V$29,5),"-") -> - | J30: =IFERROR(VLOOKUP($E30,$O$4:$V$29,6),"-") -> - | K30: =IFERROR(VLOOKUP($E30,$O$4:$V$29,7),"-") -> - | L30: =IFERROR(VLOOKUP($E30,$O$4:$V$29,8),"-") -> - | M30: =if(or('Avaliações'!D30="falta",'Avaliações'!D30=""),"-",if('Avaliações'!D30="presente", IF(IF(AND(F30="",G30="",H30=""),SUM(I30:L30)/4,SUM(F30:L30)/7)=0,"-",IF(AND(F30="",G30="",H30=""),SUM(I30:L30)/4,SUM(F30:L30)/7)))) -> -
A31: 28 | B31: =IF(Preenchimento!B37="","-",Preenchimento!B37) -> - | C31: ='Avaliações'!D31 | D31: =IF(Preenchimento!D37="","-",Preenchimento!D37) -> - | E31: =IF(Preenchimento!E37="","",Preenchimento!E37) | F31: =IFERROR(VLOOKUP($E31,$O$4:$V$29,2),"-") -> - | G31: =IFERROR(VLOOKUP($E31,$O$4:$V$29,3),"-") -> - | H31: =IFERROR(VLOOKUP($E31,$O$4:$V$29,4),"-") -> - | I31: =IFERROR(VLOOKUP($E31,$O$4:$V$29,5),"-") -> - | J31: =IFERROR(VLOOKUP($E31,$O$4:$V$29,6),"-") -> - | K31: =IFERROR(VLOOKUP($E31,$O$4:$V$29,7),"-") -> - | L31: =IFERROR(VLOOKUP($E31,$O$4:$V$29,8),"-") -> - | M31: =if(or('Avaliações'!D31="falta",'Avaliações'!D31=""),"-",if('Avaliações'!D31="presente", IF(IF(AND(F31="",G31="",H31=""),SUM(I31:L31)/4,SUM(F31:L31)/7)=0,"-",IF(AND(F31="",G31="",H31=""),SUM(I31:L31)/4,SUM(F31:L31)/7)))) -> -
A32: 29 | B32: =IF(Preenchimento!B38="","-",Preenchimento!B38) -> - | C32: ='Avaliações'!D32 | D32: =IF(Preenchimento!D38="","-",Preenchimento!D38) -> - | E32: =IF(Preenchimento!E38="","",Preenchimento!E38) | F32: =IFERROR(VLOOKUP($E32,$O$4:$V$29,2),"-") -> - | G32: =IFERROR(VLOOKUP($E32,$O$4:$V$29,3),"-") -> - | H32: =IFERROR(VLOOKUP($E32,$O$4:$V$29,4),"-") -> - | I32: =IFERROR(VLOOKUP($E32,$O$4:$V$29,5),"-") -> - | J32: =IFERROR(VLOOKUP($E32,$O$4:$V$29,6),"-") -> - | K32: =IFERROR(VLOOKUP($E32,$O$4:$V$29,7),"-") -> - | L32: =IFERROR(VLOOKUP($E32,$O$4:$V$29,8),"-") -> - | M32: =if(or('Avaliações'!D32="falta",'Avaliações'!D32=""),"-",if('Avaliações'!D32="presente", IF(IF(AND(F32="",G32="",H32=""),SUM(I32:L32)/4,SUM(F32:L32)/7)=0,"-",IF(AND(F32="",G32="",H32=""),SUM(I32:L32)/4,SUM(F32:L32)/7)))) -> -
A33: 30 | B33: =IF(Preenchimento!B39="","-",Preenchimento!B39) -> - | C33: ='Avaliações'!D33 | D33: =IF(Preenchimento!D39="","-",Preenchimento!D39) -> - | E33: =IF(Preenchimento!E39="","",Preenchimento!E39) | F33: =IFERROR(VLOOKUP($E33,$O$4:$V$29,2),"-") -> - | G33: =IFERROR(VLOOKUP($E33,$O$4:$V$29,3),"-") -> - | H33: =IFERROR(VLOOKUP($E33,$O$4:$V$29,4),"-") -> - | I33: =IFERROR(VLOOKUP($E33,$O$4:$V$29,5),"-") -> - | J33: =IFERROR(VLOOKUP($E33,$O$4:$V$29,6),"-") -> - | K33: =IFERROR(VLOOKUP($E33,$O$4:$V$29,7),"-") -> - | L33: =IFERROR(VLOOKUP($E33,$O$4:$V$29,8),"-") -> - | M33: =if(or('Avaliações'!D33="falta",'Avaliações'!D33=""),"-",if('Avaliações'!D33="presente", IF(IF(AND(F33="",G33="",H33=""),SUM(I33:L33)/4,SUM(F33:L33)/7)=0,"-",IF(AND(F33="",G33="",H33=""),SUM(I33:L33)/4,SUM(F33:L33)/7)))) -> -
A34: 31 | B34: =IF(Preenchimento!B40="","-",Preenchimento!B40) -> - | C34: ='Avaliações'!D34 | D34: =IF(Preenchimento!D40="","-",Preenchimento!D40) -> - | E34: =IF(Preenchimento!E40="","",Preenchimento!E40) | F34: =IFERROR(VLOOKUP($E34,$O$4:$V$29,2),"-") -> - | G34: =IFERROR(VLOOKUP($E34,$O$4:$V$29,3),"-") -> - | H34: =IFERROR(VLOOKUP($E34,$O$4:$V$29,4),"-") -> - | I34: =IFERROR(VLOOKUP($E34,$O$4:$V$29,5),"-") -> - | J34: =IFERROR(VLOOKUP($E34,$O$4:$V$29,6),"-") -> - | K34: =IFERROR(VLOOKUP($E34,$O$4:$V$29,7),"-") -> - | L34: =IFERROR(VLOOKUP($E34,$O$4:$V$29,8),"-") -> - | M34: =if(or('Avaliações'!D34="falta",'Avaliações'!D34=""),"-",if('Avaliações'!D34="presente", IF(IF(AND(F34="",G34="",H34=""),SUM(I34:L34)/4,SUM(F34:L34)/7)=0,"-",IF(AND(F34="",G34="",H34=""),SUM(I34:L34)/4,SUM(F34:L34)/7)))) -> -
A35: 32 | B35: =IF(Preenchimento!B41="","-",Preenchimento!B41) -> - | C35: ='Avaliações'!D35 | D35: =IF(Preenchimento!D41="","-",Preenchimento!D41) -> - | E35: =IF(Preenchimento!E41="","",Preenchimento!E41) | F35: =IFERROR(VLOOKUP($E35,$O$4:$V$29,2),"-") -> - | G35: =IFERROR(VLOOKUP($E35,$O$4:$V$29,3),"-") -> - | H35: =IFERROR(VLOOKUP($E35,$O$4:$V$29,4),"-") -> - | I35: =IFERROR(VLOOKUP($E35,$O$4:$V$29,5),"-") -> - | J35: =IFERROR(VLOOKUP($E35,$O$4:$V$29,6),"-") -> - | K35: =IFERROR(VLOOKUP($E35,$O$4:$V$29,7),"-") -> - | L35: =IFERROR(VLOOKUP($E35,$O$4:$V$29,8),"-") -> - | M35: =if(or('Avaliações'!D35="falta",'Avaliações'!D35=""),"-",if('Avaliações'!D35="presente", IF(IF(AND(F35="",G35="",H35=""),SUM(I35:L35)/4,SUM(F35:L35)/7)=0,"-",IF(AND(F35="",G35="",H35=""),SUM(I35:L35)/4,SUM(F35:L35)/7)))) -> -
A36: 33 | B36: =IF(Preenchimento!B42="","-",Preenchimento!B42) -> - | C36: ='Avaliações'!D36 | D36: =IF(Preenchimento!D42="","-",Preenchimento!D42) -> - | E36: =IF(Preenchimento!E42="","",Preenchimento!E42) | F36: =IFERROR(VLOOKUP($E36,$O$4:$V$29,2),"-") -> - | G36: =IFERROR(VLOOKUP($E36,$O$4:$V$29,3),"-") -> - | H36: =IFERROR(VLOOKUP($E36,$O$4:$V$29,4),"-") -> - | I36: =IFERROR(VLOOKUP($E36,$O$4:$V$29,5),"-") -> - | J36: =IFERROR(VLOOKUP($E36,$O$4:$V$29,6),"-") -> - | K36: =IFERROR(VLOOKUP($E36,$O$4:$V$29,7),"-") -> - | L36: =IFERROR(VLOOKUP($E36,$O$4:$V$29,8),"-") -> - | M36: =if(or('Avaliações'!D36="falta",'Avaliações'!D36=""),"-",if('Avaliações'!D36="presente", IF(IF(AND(F36="",G36="",H36=""),SUM(I36:L36)/4,SUM(F36:L36)/7)=0,"-",IF(AND(F36="",G36="",H36=""),SUM(I36:L36)/4,SUM(F36:L36)/7)))) -> -
A37: 34 | B37: =IF(Preenchimento!B43="","-",Preenchimento!B43) -> - | C37: ='Avaliações'!D37 | D37: =IF(Preenchimento!D43="","-",Preenchimento!D43) -> - | E37: =IF(Preenchimento!E43="","",Preenchimento!E43) | F37: =IFERROR(VLOOKUP($E37,$O$4:$V$29,2),"-") -> - | G37: =IFERROR(VLOOKUP($E37,$O$4:$V$29,3),"-") -> - | H37: =IFERROR(VLOOKUP($E37,$O$4:$V$29,4),"-") -> - | I37: =IFERROR(VLOOKUP($E37,$O$4:$V$29,5),"-") -> - | J37: =IFERROR(VLOOKUP($E37,$O$4:$V$29,6),"-") -> - | K37: =IFERROR(VLOOKUP($E37,$O$4:$V$29,7),"-") -> - | L37: =IFERROR(VLOOKUP($E37,$O$4:$V$29,8),"-") -> - | M37: =if(or('Avaliações'!D37="falta",'Avaliações'!D37=""),"-",if('Avaliações'!D37="presente", IF(IF(AND(F37="",G37="",H37=""),SUM(I37:L37)/4,SUM(F37:L37)/7)=0,"-",IF(AND(F37="",G37="",H37=""),SUM(I37:L37)/4,SUM(F37:L37)/7)))) -> -
A38: 35 | B38: =IF(Preenchimento!B44="","-",Preenchimento!B44) -> - | C38: ='Avaliações'!D38 | D38: =IF(Preenchimento!D44="","-",Preenchimento!D44) -> - | E38: =IF(Preenchimento!E44="","",Preenchimento!E44) | F38: =IFERROR(VLOOKUP($E38,$O$4:$V$29,2),"-") -> - | G38: =IFERROR(VLOOKUP($E38,$O$4:$V$29,3),"-") -> - | H38: =IFERROR(VLOOKUP($E38,$O$4:$V$29,4),"-") -> - | I38: =IFERROR(VLOOKUP($E38,$O$4:$V$29,5),"-") -> - | J38: =IFERROR(VLOOKUP($E38,$O$4:$V$29,6),"-") -> - | K38: =IFERROR(VLOOKUP($E38,$O$4:$V$29,7),"-") -> - | L38: =IFERROR(VLOOKUP($E38,$O$4:$V$29,8),"-") -> - | M38: =if(or('Avaliações'!D38="falta",'Avaliações'!D38=""),"-",if('Avaliações'!D38="presente", IF(IF(AND(F38="",G38="",H38=""),SUM(I38:L38)/4,SUM(F38:L38)/7)=0,"-",IF(AND(F38="",G38="",H38=""),SUM(I38:L38)/4,SUM(F38:L38)/7)))) -> -
A39: 36 | B39: =IF(Preenchimento!B45="","-",Preenchimento!B45) -> - | C39: ='Avaliações'!D39 | D39: =IF(Preenchimento!D45="","-",Preenchimento!D45) -> - | E39: =IF(Preenchimento!E45="","",Preenchimento!E45) | F39: =IFERROR(VLOOKUP($E39,$O$4:$V$29,2),"-") -> - | G39: =IFERROR(VLOOKUP($E39,$O$4:$V$29,3),"-") -> - | H39: =IFERROR(VLOOKUP($E39,$O$4:$V$29,4),"-") -> - | I39: =IFERROR(VLOOKUP($E39,$O$4:$V$29,5),"-") -> - | J39: =IFERROR(VLOOKUP($E39,$O$4:$V$29,6),"-") -> - | K39: =IFERROR(VLOOKUP($E39,$O$4:$V$29,7),"-") -> - | L39: =IFERROR(VLOOKUP($E39,$O$4:$V$29,8),"-") -> - | M39: =if(or('Avaliações'!D39="falta",'Avaliações'!D39=""),"-",if('Avaliações'!D39="presente", IF(IF(AND(F39="",G39="",H39=""),SUM(I39:L39)/4,SUM(F39:L39)/7)=0,"-",IF(AND(F39="",G39="",H39=""),SUM(I39:L39)/4,SUM(F39:L39)/7)))) -> -
A40: 37 | B40: =IF(Preenchimento!B46="","-",Preenchimento!B46) -> - | C40: ='Avaliações'!D40 | D40: =IF(Preenchimento!D46="","-",Preenchimento!D46) -> - | E40: =IF(Preenchimento!E46="","",Preenchimento!E46) | F40: =IFERROR(VLOOKUP($E40,$O$4:$V$29,2),"-") -> - | G40: =IFERROR(VLOOKUP($E40,$O$4:$V$29,3),"-") -> - | H40: =IFERROR(VLOOKUP($E40,$O$4:$V$29,4),"-") -> - | I40: =IFERROR(VLOOKUP($E40,$O$4:$V$29,5),"-") -> - | J40: =IFERROR(VLOOKUP($E40,$O$4:$V$29,6),"-") -> - | K40: =IFERROR(VLOOKUP($E40,$O$4:$V$29,7),"-") -> - | L40: =IFERROR(VLOOKUP($E40,$O$4:$V$29,8),"-") -> - | M40: =if(or('Avaliações'!D40="falta",'Avaliações'!D40=""),"-",if('Avaliações'!D40="presente", IF(IF(AND(F40="",G40="",H40=""),SUM(I40:L40)/4,SUM(F40:L40)/7)=0,"-",IF(AND(F40="",G40="",H40=""),SUM(I40:L40)/4,SUM(F40:L40)/7)))) -> -
A41: 38 | B41: =IF(Preenchimento!B47="","-",Preenchimento!B47) -> - | C41: ='Avaliações'!D41 | D41: =IF(Preenchimento!D47="","-",Preenchimento!D47) -> - | E41: =IF(Preenchimento!E47="","",Preenchimento!E47) | F41: =IFERROR(VLOOKUP($E41,$O$4:$V$29,2),"-") -> - | G41: =IFERROR(VLOOKUP($E41,$O$4:$V$29,3),"-") -> - | H41: =IFERROR(VLOOKUP($E41,$O$4:$V$29,4),"-") -> - | I41: =IFERROR(VLOOKUP($E41,$O$4:$V$29,5),"-") -> - | J41: =IFERROR(VLOOKUP($E41,$O$4:$V$29,6),"-") -> - | K41: =IFERROR(VLOOKUP($E41,$O$4:$V$29,7),"-") -> - | L41: =IFERROR(VLOOKUP($E41,$O$4:$V$29,8),"-") -> - | M41: =if(or('Avaliações'!D41="falta",'Avaliações'!D41=""),"-",if('Avaliações'!D41="presente", IF(IF(AND(F41="",G41="",H41=""),SUM(I41:L41)/4,SUM(F41:L41)/7)=0,"-",IF(AND(F41="",G41="",H41=""),SUM(I41:L41)/4,SUM(F41:L41)/7)))) -> -
... A53: 50 | B53: =IF(Preenchimento!B59="","-",Preenchimento!B59) -> - | C53: ='Avaliações'!D53 | D53: =IF(Preenchimento!D59="","-",Preenchimento!D59) -> - | E53: =IF(Preenchimento!E59="","",Preenchimento!E59) | F53: =IFERROR(VLOOKUP($E53,$O$4:$V$29,2),"-") -> - | G53: =IFERROR(VLOOKUP($E53,$O$4:$V$29,3),"-") -> - | H53: =IFERROR(VLOOKUP($E53,$O$4:$V$29,4),"-") -> - | I53: =IFERROR(VLOOKUP($E53,$O$4:$V$29,5),"-") -> - | J53: =IFERROR(VLOOKUP($E53,$O$4:$V$29,6),"-") -> - | K53: =IFERROR(VLOOKUP($E53,$O$4:$V$29,7),"-") -> - | L53: =IFERROR(VLOOKUP($E53,$O$4:$V$29,8),"-") -> - | M53: =if(or('Avaliações'!D53="falta",'Avaliações'!D53=""),"-",if('Avaliações'!D53="presente", IF(IF(AND(F53="",G53="",H53=""),SUM(I53:L53)/4,SUM(F53:L53)/7)=0,"-",IF(AND(F53="",G53="",H53=""),SUM(I53:L53)/4,SUM(F53:L53)/7)))) -> -
A54: 51 | B54: =IF(Preenchimento!B60="","-",Preenchimento!B60) -> - | C54: ='Avaliações'!D54 | D54: =IF(Preenchimento!D60="","-",Preenchimento!D60) -> - | E54: =IF(Preenchimento!E60="","",Preenchimento!E60) | F54: =IFERROR(VLOOKUP($E54,$O$4:$V$29,2),"-") -> - | G54: =IFERROR(VLOOKUP($E54,$O$4:$V$29,3),"-") -> - | H54: =IFERROR(VLOOKUP($E54,$O$4:$V$29,4),"-") -> - | I54: =IFERROR(VLOOKUP($E54,$O$4:$V$29,5),"-") -> - | J54: =IFERROR(VLOOKUP($E54,$O$4:$V$29,6),"-") -> - | K54: =IFERROR(VLOOKUP($E54,$O$4:$V$29,7),"-") -> - | L54: =IFERROR(VLOOKUP($E54,$O$4:$V$29,8),"-") -> - | M54: =IF(OR('Avaliações'!D54="falta",'Avaliações'!D54=""),"-",IF('Avaliações'!D54="presente", IF(IF(AND(F54="",G54="",H54=""),SUM(I54:L54)/4,SUM(F54:L54)/7)=0,"-",IF(AND(F54="",G54="",H54=""),SUM(I54:L54)/4,SUM(F54:L54)/7)))) -> -
A55: 52 | B55: =IF(Preenchimento!B61="","-",Preenchimento!B61) -> - | C55: ='Avaliações'!D55 | D55: =IF(Preenchimento!D61="","-",Preenchimento!D61) -> - | E55: =IF(Preenchimento!E61="","",Preenchimento!E61) | F55: =IFERROR(VLOOKUP($E55,$O$4:$V$29,2),"-") -> - | G55: =IFERROR(VLOOKUP($E55,$O$4:$V$29,3),"-") -> - | H55: =IFERROR(VLOOKUP($E55,$O$4:$V$29,4),"-") -> - | I55: =IFERROR(VLOOKUP($E55,$O$4:$V$29,5),"-") -> - | J55: =IFERROR(VLOOKUP($E55,$O$4:$V$29,6),"-") -> - | K55: =IFERROR(VLOOKUP($E55,$O$4:$V$29,7),"-") -> - | L55: =IFERROR(VLOOKUP($E55,$O$4:$V$29,8),"-") -> - | M55: =IF(OR('Avaliações'!D55="falta",'Avaliações'!D55=""),"-",IF('Avaliações'!D55="presente", IF(IF(AND(F55="",G55="",H55=""),SUM(I55:L55)/4,SUM(F55:L55)/7)=0,"-",IF(AND(F55="",G55="",H55=""),SUM(I55:L55)/4,SUM(F55:L55)/7)))) -> -
A56: 53 | B56: =IF(Preenchimento!B62="","-",Preenchimento!B62) -> - | C56: ='Avaliações'!D56 | D56: =IF(Preenchimento!D62="","-",Preenchimento!D62) -> - | E56: =IF(Preenchimento!E62="","",Preenchimento!E62) | F56: =IFERROR(VLOOKUP($E56,$O$4:$V$29,2),"-") -> - | G56: =IFERROR(VLOOKUP($E56,$O$4:$V$29,3),"-") -> - | H56: =IFERROR(VLOOKUP($E56,$O$4:$V$29,4),"-") -> - | I56: =IFERROR(VLOOKUP($E56,$O$4:$V$29,5),"-") -> - | J56: =IFERROR(VLOOKUP($E56,$O$4:$V$29,6),"-") -> - | K56: =IFERROR(VLOOKUP($E56,$O$4:$V$29,7),"-") -> - | L56: =IFERROR(VLOOKUP($E56,$O$4:$V$29,8),"-") -> - | M56: =IF(OR('Avaliações'!D56="falta",'Avaliações'!D56=""),"-",IF('Avaliações'!D56="presente", IF(IF(AND(F56="",G56="",H56=""),SUM(I56:L56)/4,SUM(F56:L56)/7)=0,"-",IF(AND(F56="",G56="",H56=""),SUM(I56:L56)/4,SUM(F56:L56)/7)))) -> -
A57: 54 | B57: =IF(Preenchimento!B63="","-",Preenchimento!B63) -> - | C57: ='Avaliações'!D57 | D57: =IF(Preenchimento!D63="","-",Preenchimento!D63) -> - | E57: =IF(Preenchimento!E63="","",Preenchimento!E63) | F57: =IFERROR(VLOOKUP($E57,$O$4:$V$29,2),"-") -> - | G57: =IFERROR(VLOOKUP($E57,$O$4:$V$29,3),"-") -> - | H57: =IFERROR(VLOOKUP($E57,$O$4:$V$29,4),"-") -> - | I57: =IFERROR(VLOOKUP($E57,$O$4:$V$29,5),"-") -> - | J57: =IFERROR(VLOOKUP($E57,$O$4:$V$29,6),"-") -> - | K57: =IFERROR(VLOOKUP($E57,$O$4:$V$29,7),"-") -> - | L57: =IFERROR(VLOOKUP($E57,$O$4:$V$29,8),"-") -> - | M57: =IF(OR('Avaliações'!D57="falta",'Avaliações'!D57=""),"-",IF('Avaliações'!D57="presente", IF(IF(AND(F57="",G57="",H57=""),SUM(I57:L57)/4,SUM(F57:L57)/7)=0,"-",IF(AND(F57="",G57="",H57=""),SUM(I57:L57)/4,SUM(F57:L57)/7)))) -> -
A58: 55 | B58: =IF(Preenchimento!B64="","-",Preenchimento!B64) -> - | C58: ='Avaliações'!D58 | D58: =IF(Preenchimento!D64="","-",Preenchimento!D64) -> - | E58: =IF(Preenchimento!E64="","",Preenchimento!E64) | F58: =IFERROR(VLOOKUP($E58,$O$4:$V$29,2),"-") -> - | G58: =IFERROR(VLOOKUP($E58,$O$4:$V$29,3),"-") -> - | H58: =IFERROR(VLOOKUP($E58,$O$4:$V$29,4),"-") -> - | I58: =IFERROR(VLOOKUP($E58,$O$4:$V$29,5),"-") -> - | J58: =IFERROR(VLOOKUP($E58,$O$4:$V$29,6),"-") -> - | K58: =IFERROR(VLOOKUP($E58,$O$4:$V$29,7),"-") -> - | L58: =IFERROR(VLOOKUP($E58,$O$4:$V$29,8),"-") -> - | M58: =IF(OR('Avaliações'!D58="falta",'Avaliações'!D58=""),"-",IF('Avaliações'!D58="presente", IF(IF(AND(F58="",G58="",H58=""),SUM(I58:L58)/4,SUM(F58:L58)/7)=0,"-",IF(AND(F58="",G58="",H58=""),SUM(I58:L58)/4,SUM(F58:L58)/7)))) -> -
A59: 56 | B59: =IF(Preenchimento!B65="","-",Preenchimento!B65) -> - | C59: ='Avaliações'!D59 | D59: =IF(Preenchimento!D65="","-",Preenchimento!D65) -> - | E59: =IF(Preenchimento!E65="","",Preenchimento!E65) | F59: =IFERROR(VLOOKUP($E59,$O$4:$V$29,2),"-") -> - | G59: =IFERROR(VLOOKUP($E59,$O$4:$V$29,3),"-") -> - | H59: =IFERROR(VLOOKUP($E59,$O$4:$V$29,4),"-") -> - | I59: =IFERROR(VLOOKUP($E59,$O$4:$V$29,5),"-") -> - | J59: =IFERROR(VLOOKUP($E59,$O$4:$V$29,6),"-") -> - | K59: =IFERROR(VLOOKUP($E59,$O$4:$V$29,7),"-") -> - | L59: =IFERROR(VLOOKUP($E59,$O$4:$V$29,8),"-") -> - | M59: =IF(OR('Avaliações'!D59="falta",'Avaliações'!D59=""),"-",IF('Avaliações'!D59="presente", IF(IF(AND(F59="",G59="",H59=""),SUM(I59:L59)/4,SUM(F59:L59)/7)=0,"-",IF(AND(F59="",G59="",H59=""),SUM(I59:L59)/4,SUM(F59:L59)/7)))) -> -
A60: 57 | B60: =IF(Preenchimento!B66="","-",Preenchimento!B66) -> - | C60: ='Avaliações'!D60 | D60: =IF(Preenchimento!D66="","-",Preenchimento!D66) -> - | E60: =IF(Preenchimento!E66="","",Preenchimento!E66) | F60: =IFERROR(VLOOKUP($E60,$O$4:$V$29,2),"-") -> - | G60: =IFERROR(VLOOKUP($E60,$O$4:$V$29,3),"-") -> - | H60: =IFERROR(VLOOKUP($E60,$O$4:$V$29,4),"-") -> - | I60: =IFERROR(VLOOKUP($E60,$O$4:$V$29,5),"-") -> - | J60: =IFERROR(VLOOKUP($E60,$O$4:$V$29,6),"-") -> - | K60: =IFERROR(VLOOKUP($E60,$O$4:$V$29,7),"-") -> - | L60: =IFERROR(VLOOKUP($E60,$O$4:$V$29,8),"-") -> - | M60: =IF(OR('Avaliações'!D60="falta",'Avaliações'!D60=""),"-",IF('Avaliações'!D60="presente", IF(IF(AND(F60="",G60="",H60=""),SUM(I60:L60)/4,SUM(F60:L60)/7)=0,"-",IF(AND(F60="",G60="",H60=""),SUM(I60:L60)/4,SUM(F60:L60)/7)))) -> -
A61: 58 | B61: =IF(Preenchimento!B67="","-",Preenchimento!B67) -> - | C61: ='Avaliações'!D61 | D61: =IF(Preenchimento!D67="","-",Preenchimento!D67) -> - | E61: =IF(Preenchimento!E67="","",Preenchimento!E67) | F61: =IFERROR(VLOOKUP($E61,$O$4:$V$29,2),"-") -> - | G61: =IFERROR(VLOOKUP($E61,$O$4:$V$29,3),"-") -> - | H61: =IFERROR(VLOOKUP($E61,$O$4:$V$29,4),"-") -> - | I61: =IFERROR(VLOOKUP($E61,$O$4:$V$29,5),"-") -> - | J61: =IFERROR(VLOOKUP($E61,$O$4:$V$29,6),"-") -> - | K61: =IFERROR(VLOOKUP($E61,$O$4:$V$29,7),"-") -> - | L61: =IFERROR(VLOOKUP($E61,$O$4:$V$29,8),"-") -> - | M61: =IF(OR('Avaliações'!D61="falta",'Avaliações'!D61=""),"-",IF('Avaliações'!D61="presente", IF(IF(AND(F61="",G61="",H61=""),SUM(I61:L61)/4,SUM(F61:L61)/7)=0,"-",IF(AND(F61="",G61="",H61=""),SUM(I61:L61)/4,SUM(F61:L61)/7)))) -> -
A62: 59 | B62: =IF(Preenchimento!B68="","-",Preenchimento!B68) -> - | C62: ='Avaliações'!D62 | D62: =IF(Preenchimento!D68="","-",Preenchimento!D68) -> - | E62: =IF(Preenchimento!E68="","",Preenchimento!E68) | F62: =IFERROR(VLOOKUP($E62,$O$4:$V$29,2),"-") -> - | G62: =IFERROR(VLOOKUP($E62,$O$4:$V$29,3),"-") -> - | H62: =IFERROR(VLOOKUP($E62,$O$4:$V$29,4),"-") -> - | I62: =IFERROR(VLOOKUP($E62,$O$4:$V$29,5),"-") -> - | J62: =IFERROR(VLOOKUP($E62,$O$4:$V$29,6),"-") -> - | K62: =IFERROR(VLOOKUP($E62,$O$4:$V$29,7),"-") -> - | L62: =IFERROR(VLOOKUP($E62,$O$4:$V$29,8),"-") -> - | M62: =IF(OR('Avaliações'!D62="falta",'Avaliações'!D62=""),"-",IF('Avaliações'!D62="presente", IF(IF(AND(F62="",G62="",H62=""),SUM(I62:L62)/4,SUM(F62:L62)/7)=0,"-",IF(AND(F62="",G62="",H62=""),SUM(I62:L62)/4,SUM(F62:L62)/7)))) -> -
A63: 60 | B63: =IF(Preenchimento!B69="","-",Preenchimento!B69) -> - | C63: ='Avaliações'!D63 | D63: =IF(Preenchimento!D69="","-",Preenchimento!D69) -> - | E63: =IF(Preenchimento!E69="","",Preenchimento!E69) | F63: =IFERROR(VLOOKUP($E63,$O$4:$V$29,2),"-") -> - | G63: =IFERROR(VLOOKUP($E63,$O$4:$V$29,3),"-") -> - | H63: =IFERROR(VLOOKUP($E63,$O$4:$V$29,4),"-") -> - | I63: =IFERROR(VLOOKUP($E63,$O$4:$V$29,5),"-") -> - | J63: =IFERROR(VLOOKUP($E63,$O$4:$V$29,6),"-") -> - | K63: =IFERROR(VLOOKUP($E63,$O$4:$V$29,7),"-") -> - | L63: =IFERROR(VLOOKUP($E63,$O$4:$V$29,8),"-") -> - | M63: =IF(OR('Avaliações'!D63="falta",'Avaliações'!D63=""),"-",IF('Avaliações'!D63="presente", IF(IF(AND(F63="",G63="",H63=""),SUM(I63:L63)/4,SUM(F63:L63)/7)=0,"-",IF(AND(F63="",G63="",H63=""),SUM(I63:L63)/4,SUM(F63:L63)/7)))) -> -
A64: 61 | B64: =IF(Preenchimento!B70="","-",Preenchimento!B70) -> - | C64: ='Avaliações'!D64 | D64: =IF(Preenchimento!D70="","-",Preenchimento!D70) -> - | E64: =IF(Preenchimento!E70="","",Preenchimento!E70) | F64: =IFERROR(VLOOKUP($E64,$O$4:$V$29,2),"-") -> - | G64: =IFERROR(VLOOKUP($E64,$O$4:$V$29,3),"-") -> - | H64: =IFERROR(VLOOKUP($E64,$O$4:$V$29,4),"-") -> - | I64: =IFERROR(VLOOKUP($E64,$O$4:$V$29,5),"-") -> - | J64: =IFERROR(VLOOKUP($E64,$O$4:$V$29,6),"-") -> - | K64: =IFERROR(VLOOKUP($E64,$O$4:$V$29,7),"-") -> - | L64: =IFERROR(VLOOKUP($E64,$O$4:$V$29,8),"-") -> - | M64: =IF(OR('Avaliações'!D64="falta",'Avaliações'!D64=""),"-",IF('Avaliações'!D64="presente", IF(IF(AND(F64="",G64="",H64=""),SUM(I64:L64)/4,SUM(F64:L64)/7)=0,"-",IF(AND(F64="",G64="",H64=""),SUM(I64:L64)/4,SUM(F64:L64)/7)))) -> -
...

Sheet Resultados
B1: Nota Final
B2: Nome | C2: Função | D2: Treinamentos | E2: Avaliação 1 | F2: Avaliação 2 | G2: DPO | H2: Noite Cultural | I2: Nota final
A3: 1 | B3: =IF(Preenchimento!B10="","-",Preenchimento!B10) -> - | C3: =IF(Preenchimento!D10="","-",Preenchimento!D10) -> - | D3: =Treinamentos!H3 -> - | E3: =IFERROR(AVERAGE('Avaliações'!E4:N4),"Sem Nota") -> Sem Nota | F3: =IFERROR(AVERAGE('Avaliações'!O4:X4),"Sem Nota") -> Sem Nota | G3: =DPO!I3 -> - | H3: =IF(NC!M4="-","-",IF(Preenchimento!$F$7="Stand e Apresentação de Palco",(SUM(NC!F4:L4)/7),IF(Preenchimento!$F$7="Stand",(SUM(NC!I4:L4)/4),"S.N.C"))) -> - | I3: =IFERROR(IF(AND(D3="online",H3="S.N.C"),1+E3*0.25+F3*0.25+G3*0.1+3,IF(D3="online",1+E3*0.25+F3*0.25+G3*0.1+H3*0.3,IF(H3="S.N.C",D3*0.1+E3*0.25+F3*0.25+G3*0.1+3,D3*0.1+E3*0.25+F3*0.25+G3*0.1+H3*0.3))),"-") -> -
A4: 2 | B4: =IF(Preenchimento!B11="","-",Preenchimento!B11) -> - | C4: =IF(Preenchimento!D11="","-",Preenchimento!D11) -> - | D4: =Treinamentos!H4 -> - | E4: =IFERROR(AVERAGE('Avaliações'!E5:N5),"Sem Nota") -> Sem Nota | F4: =IFERROR(AVERAGE('Avaliações'!O5:X5),"Sem Nota") -> Sem Nota | G4: =DPO!I4 -> - | H4: =IF(NC!M5="-","-",IF(Preenchimento!$F$7="Stand e Apresentação de Palco",(SUM(NC!F5:L5)/7),IF(Preenchimento!$F$7="Stand",(SUM(NC!I5:L5)/4),"S.N.C"))) -> - | I4: =IFERROR(IF(AND(D4="online",H4="S.N.C"),1+E4*0.25+F4*0.25+G4*0.1+3,IF(D4="online",1+E4*0.25+F4*0.25+G4*0.1+H4*0.3,IF(H4="S.N.C",D4*0.1+E4*0.25+F4*0.25+G4*0.1+3,D4*0.1+E4*0.25+F4*0.25+G4*0.1+H4*0.3))),"-") -> -
A5: 3 | B5: =IF(Preenchimento!B12="","-",Preenchimento!B12) -> - | C5: =IF(Preenchimento!D12="","-",Preenchimento!D12) -> - | D5: =Treinamentos!H5 -> - | E5: =IFERROR(AVERAGE('Avaliações'!E6:N6),"Sem Nota") -> Sem Nota | F5: =IFERROR(AVERAGE('Avaliações'!O6:X6),"Sem Nota") -> Sem Nota | G5: =DPO!I5 -> - | H5: =IF(NC!M6="-","-",IF(Preenchimento!$F$7="Stand e Apresentação de Palco",(SUM(NC!F6:L6)/7),IF(Preenchimento!$F$7="Stand",(SUM(NC!I6:L6)/4),"S.N.C"))) -> - | I5: =IFERROR(IF(AND(D5="online",H5="S.N.C"),1+E5*0.25+F5*0.25+G5*0.1+3,IF(D5="online",1+E5*0.25+F5*0.25+G5*0.1+H5*0.3,IF(H5="S.N.C",D5*0.1+E5*0.25+F5*0.25+G5*0.1+3,D5*0.1+E5*0.25+F5*0.25+G5*0.1+H5*0.3))),"-") -> -
A6: 4 | B6: =IF(Preenchimento!B13="","-",Preenchimento!B13) -> - | C6: =IF(Preenchimento!D13="","-",Preenchimento!D13) -> - | D6: =Treinamentos!H6 -> - | E6: =IFERROR(AVERAGE('Avaliações'!E7:N7),"Sem Nota") -> Sem Nota | F6: =IFERROR(AVERAGE('Avaliações'!O7:X7),"Sem Nota") -> Sem Nota | G6: =DPO!I6 -> - | H6: =IF(NC!M7="-","-",IF(Preenchimento!$F$7="Stand e Apresentação de Palco",(SUM(NC!F7:L7)/7),IF(Preenchimento!$F$7="Stand",(SUM(NC!I7:L7)/4),"S.N.C"))) -> - | I6: =IFERROR(IF(AND(D6="online",H6="S.N.C"),1+E6*0.25+F6*0.25+G6*0.1+3,IF(D6="online",1+E6*0.25+F6*0.25+G6*0.1+H6*0.3,IF(H6="S.N.C",D6*0.1+E6*0.25+F6*0.25+G6*0.1+3,D6*0.1+E6*0.25+F6*0.25+G6*0.1+H6*0.3))),"-") -> -
A7: 5 | B7: =IF(Preenchimento!B14="","-",Preenchimento!B14) -> - | C7: =IF(Preenchimento!D14="","-",Preenchimento!D14) -> - | D7: =Treinamentos!H7 -> - | E7: =IFERROR(AVERAGE('Avaliações'!E8:N8),"Sem Nota") -> Sem Nota | F7: =IFERROR(AVERAGE('Avaliações'!O8:X8),"Sem Nota") -> Sem Nota | G7: =DPO!I7 -> - | H7: =IF(NC!M8="-","-",IF(Preenchimento!$F$7="Stand e Apresentação de Palco",(SUM(NC!F8:L8)/7),IF(Preenchimento!$F$7="Stand",(SUM(NC!I8:L8)/4),"S.N.C"))) -> - | I7: =IFERROR(IF(AND(D7="online",H7="S.N.C"),1+E7*0.25+F7*0.25+G7*0.1+3,IF(D7="online",1+E7*0.25+F7*0.25+G7*0.1+H7*0.3,IF(H7="S.N.C",D7*0.1+E7*0.25+F7*0.25+G7*0.1+3,D7*0.1+E7*0.25+F7*0.25+G7*0.1+H7*0.3))),"-") -> -
A8: 6 | B8: =IF(Preenchimento!B15="","-",Preenchimento!B15) -> - | C8: =IF(Preenchimento!D15="","-",Preenchimento!D15) -> - | D8: =Treinamentos!H8 -> - | E8: =IFERROR(AVERAGE('Avaliações'!E9:N9),"Sem Nota") -> Sem Nota | F8: =IFERROR(AVERAGE('Avaliações'!O9:X9),"Sem Nota") -> Sem Nota | G8: =DPO!I8 -> - | H8: =IF(NC!M9="-","-",IF(Preenchimento!$F$7="Stand e Apresentação de Palco",(SUM(NC!F9:L9)/7),IF(Preenchimento!$F$7="Stand",(SUM(NC!I9:L9)/4),"S.N.C"))) -> - | I8: =IFERROR(IF(AND(D8="online",H8="S.N.C"),1+E8*0.25+F8*0.25+G8*0.1+3,IF(D8="online",1+E8*0.25+F8*0.25+G8*0.1+H8*0.3,IF(H8="S.N.C",D8*0.1+E8*0.25+F8*0.25+G8*0.1+3,D8*0.1+E8*0.25+F8*0.25+G8*0.1+H8*0.3))),"-") -> -
A9: 7 | B9: =IF(Preenchimento!B16="","-",Preenchimento!B16) -> - | C9: =IF(Preenchimento!D16="","-",Preenchimento!D16) -> - | D9: =Treinamentos!H9 -> - | E9: =IFERROR(AVERAGE('Avaliações'!E10:N10),"Sem Nota") -> Sem Nota | F9: =IFERROR(AVERAGE('Avaliações'!O10:X10),"Sem Nota") -> Sem Nota | G9: =DPO!I9 -> - | H9: =IF(NC!M10="-","-",IF(Preenchimento!$F$7="Stand e Apresentação de Palco",(SUM(NC!F10:L10)/7),IF(Preenchimento!$F$7="Stand",(SUM(NC!I10:L10)/4),"S.N.C"))) -> - | I9: =IFERROR(IF(AND(D9="online",H9="S.N.C"),1+E9*0.25+F9*0.25+G9*0.1+3,IF(D9="online",1+E9*0.25+F9*0.25+G9*0.1+H9*0.3,IF(H9="S.N.C",D9*0.1+E9*0.25+F9*0.25+G9*0.1+3,D9*0.1+E9*0.25+F9*0.25+G9*0.1+H9*0.3))),"-") -> -
A10: 8 | B10: =IF(Preenchimento!B17="","-",Preenchimento!B17) -> - | C10: =IF(Preenchimento!D17="","-",Preenchimento!D17) -> - | D10: =Treinamentos!H10 -> - | E10: =IFERROR(AVERAGE('Avaliações'!E11:N11),"Sem Nota") -> Sem Nota | F10: =IFERROR(AVERAGE('Avaliações'!O11:X11),"Sem Nota") -> Sem Nota | G10: =DPO!I10 -> - | H10: =IF(NC!M11="-","-",IF(Preenchimento!$F$7="Stand e Apresentação de Palco",(SUM(NC!F11:L11)/7),IF(Preenchimento!$F$7="Stand",(SUM(NC!I11:L11)/4),"S.N.C"))) -> - | I10: =IFERROR(IF(AND(D10="online",H10="S.N.C"),1+E10*0.25+F10*0.25+G10*0.1+3,IF(D10="online",1+E10*0.25+F10*0.25+G10*0.1+H10*0.3,IF(H10="S.N.C",D10*0.1+E10*0.25+F10*0.25+G10*0.1+3,D10*0.1+E10*0.25+F10*0.25+G10*0.1+H10*0.3))),"-") -> -
A11: 9 | B11: =IF(Preenchimento!B18="","-",Preenchimento!B18) -> - | C11: =IF(Preenchimento!D18="","-",Preenchimento!D18) -> - | D11: =Treinamentos!H11 -> - | E11: =IFERROR(AVERAGE('Avaliações'!E12:N12),"Sem Nota") -> Sem Nota | F11: =IFERROR(AVERAGE('Avaliações'!O12:X12),"Sem Nota") -> Sem Nota | G11: =DPO!I11 -> - | H11: =IF(NC!M12="-","-",IF(Preenchimento!$F$7="Stand e Apresentação de Palco",(SUM(NC!F12:L12)/7),IF(Preenchimento!$F$7="Stand",(SUM(NC!I12:L12)/4),"S.N.C"))) -> - | I11: =IFERROR(IF(AND(D11="online",H11="S.N.C"),1+E11*0.25+F11*0.25+G11*0.1+3,IF(D11="online",1+E11*0.25+F11*0.25+G11*0.1+H11*0.3,IF(H11="S.N.C",D11*0.1+E11*0.25+F11*0.25+G11*0.1+3,D11*0.1+E11*0.25+F11*0.25+G11*0.1+H11*0.3))),"-") -> -
A12: 10 | B12: =IF(Preenchimento!B19="","-",Preenchimento!B19) -> - | C12: =IF(Preenchimento!D19="","-",Preenchimento!D19) -> - | D12: =Treinamentos!H12 -> - | E12: =IFERROR(AVERAGE('Avaliações'!E13:N13),"Sem Nota") -> Sem Nota | F12: =IFERROR(AVERAGE('Avaliações'!O13:X13),"Sem Nota") -> Sem Nota | G12: =DPO!I12 -> - | H12: =IF(NC!M13="-","-",IF(Preenchimento!$F$7="Stand e Apresentação de Palco",(SUM(NC!F13:L13)/7),IF(Preenchimento!$F$7="Stand",(SUM(NC!I13:L13)/4),"S.N.C"))) -> - | I12: =IFERROR(IF(AND(D12="online",H12="S.N.C"),1+E12*0.25+F12*0.25+G12*0.1+3,IF(D12="online",1+E12*0.25+F12*0.25+G12*0.1+H12*0.3,IF(H12="S.N.C",D12*0.1+E12*0.25+F12*0.25+G12*0.1+3,D12*0.1+E12*0.25+F12*0.25+G12*0.1+H12*0.3))),"-") -> -
A13: 11 | B13: =IF(Preenchimento!B20="","-",Preenchimento!B20) -> - | C13: =IF(Preenchimento!D20="","-",Preenchimento!D20) -> - | D13: =Treinamentos!H13 -> - | E13: =IFERROR(AVERAGE('Avaliações'!E14:N14),"Sem Nota") -> Sem Nota | F13: =IFERROR(AVERAGE('Avaliações'!O14:X14),"Sem Nota") -> Sem Nota | G13: =DPO!I13 -> - | H13: =IF(NC!M14="-","-",IF(Preenchimento!$F$7="Stand e Apresentação de Palco",(SUM(NC!F14:L14)/7),IF(Preenchimento!$F$7="Stand",(SUM(NC!I14:L14)/4),"S.N.C"))) -> - | I13: =IFERROR(IF(AND(D13="online",H13="S.N.C"),1+E13*0.25+F13*0.25+G13*0.1+3,IF(D13="online",1+E13*0.25+F13*0.25+G13*0.1+H13*0.3,IF(H13="S.N.C",D13*0.1+E13*0.25+F13*0.25+G13*0.1+3,D13*0.1+E13*0.25+F13*0.25+G13*0.1+H13*0.3))),"-") -> -
