Workbook

Sheet Preenchimento
A1: Controle Avaliação
A2: Preenchimento — lista-mãe do comitê
B4: Preencha um delegado por linha, a partir da linha 10. A ordem desta aba comanda o Registro por Sessão e a aba Nota.
B5: Delegado e Representação/Função são preenchidos pela equipe. Presença geral é a presença consolidada do evento.
B6: Não insira nem exclua linhas: as demais abas referenciam estas posições fixas.
B9: Delegado | C9: Representação/Função | D9: Presença geral
A10: =IF($B10="","",ROW()-9)
A11: =IF($B11="","",ROW()-9)
A12: =IF($B12="","",ROW()-9)
A13: =IF($B13="","",ROW()-9)
A14: =IF($B14="","",ROW()-9)
A15: =IF($B15="","",ROW()-9)
A16: =IF($B16="","",ROW()-9)
A17: =IF($B17="","",ROW()-9)
A18: =IF($B18="","",ROW()-9)
A19: =IF($B19="","",ROW()-9)
A20: =IF($B20="","",ROW()-9)
A21: =IF($B21="","",ROW()-9)
... A109: =IF($B109="","",ROW()-9)

Sheet Rubrica
A1: Controle Avaliação
A2: Rubrica — referência operacional
B4: 1. Eixos e notas base
B5: Eixo | C5: O que mede | D5: Nota base | E5: Pergunta avaliativa central
B6: Diplomacia e Respeito às Regras | C6: Postura, decoro, domínio procedimental, relação com a presidência | D6: 8 | E6: Atuou com postura adequada e respeito ao procedimento?
B7: Fidelidade à Função Designada | C7: Coerência com o papel atribuído (política externa para delegações; condução neutra para presidência) | D7: 8 | E7: Foi coerente com o papel que recebeu?
B8: Contribuição | C8: Impacto e avanço material: proposta, cláusula, documento, acordo, destravamento, organização de solução, materialização | D8: 5 | E8: Fez o comitê avançar concretamente?
B9: Participação | C9: Presença ativa, regularidade e volume de engajamento nas sessões | D9: 5 | E9: Esteve presente e ativo nas sessões?
B10: Base 8 (Diplomacia, Fidelidade): presunção de adequação — a nota se move para cima ou para baixo apenas mediante gatilho registrado.
B11: Base 5 (Contribuição, Participação): nada é presumido — a nota só sobe mediante atuação demonstrada e registrada.
B12: Participação alta não compensa Contribuição baixa. Os dois eixos são registrados de forma independente.
B14: 2. Gatilhos pontuáveis (campo Gatilho)
B15: Neste Controle Avaliação, o campo Gatilho usa tokens pontuáveis: cada token soma ou subtrai pontos diretamente na nota do eixo.
B16: Os tokens não são os IDs fixos do catálogo da Matriz de Avaliação — ver specs/ERRATA_GATILHOS_PONTUAVEIS.md (decisão registrada do projeto).
B17: Formato: D+X / D-Y, F+X / F-Y, C+X / C-Y, P+X / P-Y, com X e Y inteiros. Validação recomendada: valores de -8 até +5.
B18: Vários tokens no mesmo campo, separados por ponto e vírgula (até 8 tokens por campo). Exemplo: C+2; C-1
B19: Nota Preliminar = nota base do eixo + soma dos tokens, sempre limitada entre 0 e 10.
B20: Tokens de outro eixo ou texto inválido são ignorados pela fórmula. Presença na sessão = Falta gera nota "-".
B21: Cada token exige Evidência correspondente no mesmo eixo e na mesma sessão. A fórmula organiza a pontuação; ela não substitui a análise nem a revisão acadêmica.
B22: Exemplo de Gatilho | C22: Eixo | D22: Cálculo | E22: Nota Preliminar
B23: C+2 | C23: Contribuição | D23: 5 + 2 | E23: 7
B24: C+2; C-1 | C24: Contribuição | D24: 5 + 2 - 1 | E24: 6
B25: D+1; D-2 | C25: Diplomacia e Respeito às Regras | D25: 8 + 1 - 2 | E25: 7
B26: F+2; F-1 | C26: Fidelidade à Função Designada | D26: 8 + 2 - 1 | E26: 9
B27: P-2 | C27: Participação | D27: 5 - 2 | E27: 3
B29: 3. Escala de interpretação (0 a 10)
B30: Nota | C30: Interpretação
B31: 10 | C31: Desempenho excepcional: evidência clara, impacto decisivo, aderência plena ao eixo
B32: 9 | C32: Desempenho destacado: evidência concreta, impacto relevante
B33: 8 | C33: Desempenho adequado ou bom, compatível com o esperado
B34: 7 | C34: Desempenho aceitável, com pequenos limites ou irregularidades
B35: 6 | C35: Desempenho limitado, irregular ou pouco consistente
B36: 5 | C36: Desempenho mediano, mínimo ou insuficientemente demonstrado
B37: 4 | C37: Problema relevante ou baixa atuação no eixo
B38: 3 | C38: Problema grave, repetido ou impacto negativo claro
B39: 2 | C39: Atuação muito insuficiente ou fortemente incompatível com o eixo
B40: 1 | C40: Atuação quase inexistente ou conduta extremamente prejudicial
B41: 0 | C41: Ausência total de atuação avaliável ou conduta incompatível com avaliação no eixo
B42: A mesma nota tem significado diferente conforme a base do eixo: 5 em Contribuição é atuação mediana; 5 em Diplomacia é queda de 3 pontos abaixo da base.
B44: 4. Travas de registro
...

Sheet Registro por Sessão
A1: Controle Avaliação — Registro por Sessão
A2: Identificação | G2: Diplomacia e Respeito às Regras | K2: Fidelidade à Função Designada | O2: Contribuição | S2: Participação | W2: Síntese
B3: Sessão | C3: Delegado | D3: Representação/Função | E3: Presença na sessão | F3: Status do registro | G3: Evidência D | H3: Gatilho D | I3: Triagem D | J3: Nota Preliminar D | K3: Evidência F | L3: Gatilho F | M3: Triagem F | N3: Nota Preliminar F | O3: Evidência C | P3: Gatilho C | Q3: Triagem C | R3: Nota Preliminar C | S3: Evidência P | T3: Gatilho P | U3: Triagem P | V3: Nota Preliminar P | W3: Síntese acumulada da sessão | X3: Observação geral da sessão
A4: =IF($C4="","",1) | B4: =IF($C4="","","1ª Sessão") | C4: =IF(Preenchimento!$B$10="","",Preenchimento!$B$10) | D4: =IF($C4="","",IF(Preenchimento!$C$10="","-",Preenchimento!$C$10)) | J4: =IF($C4="","",IF($E4="Falta","-",MAX(0,MIN(10,8+IFERROR(VALUE(TRIM(MID(SUBSTITUTE(SUBSTITUTE(SUBSTITUTE(UPPER($H4)," ",""),"D",""),";",REPT(" ",30)),1,30))),0)+IFERROR(VALUE(TRIM(MID(SUBSTITUTE(SUBSTITUTE(SUBSTITUTE(UPPER($H4)," ",""),"D",""),";",REPT(" ",30)),31,30))),0)+IFERROR(VALUE(TRIM(MID(SUBSTITUTE(SUBSTITUTE(SUBSTITUTE(UPPER($H4)," ",""),"D",""),";",REPT(" ",30)),61,30))),0)+IFERROR(VALUE(TRIM(MID(SUBSTITUTE(SUBSTITUTE(SUBSTITUTE(UPPER($H4)," ",""),"D",""),";",REPT(" ",30)),91,30))),0)+IFERROR(VALUE(TRIM(MID(SUBSTITUTE(SUBSTITUTE(SUBSTITUTE(UPPER($H4)," ",""),"D",""),";",REPT(" ",30)),121,30))),0)+IFERROR(VALUE(TRIM(MID(SUBSTITUTE(SUBSTITUTE(SUBSTITUTE(UPPER($H4)," ",""),"D",""),";",REPT(" ",30)),151,30))),0)+IFERROR(VALUE(TRIM(MID(SUBSTITUTE(SUBSTITUTE(SUBSTITUTE(UPPER($H4)," ",""),"D",""),";",REPT(" ",30)),181,30))),0)+IFERROR(VALUE(TRIM(MID(SUBSTITUTE(SUBSTITUTE(SUBSTITUTE(UPPER($H4)," ",""),"D",""),";",REPT(" ",30)),211,30))),0))))) | N4: =IF($C4="","",IF($E4="Falta","-",MAX(0,MIN(10,8+IFERROR(VALUE(TRIM(MID(SUBSTITUTE(SUBSTITUTE(SUBSTITUTE(UPPER($L4)," ",""),"F",""),";",REPT(" ",30)),1,30))),0)+IFERROR(VALUE(TRIM(MID(SUBSTITUTE(SUBSTITUTE(SUBSTITUTE(UPPER($L4)," ",""),"F",""),";",REPT(" ",30)),31,30))),0)+IFERROR(VALUE(TRIM(MID(SUBSTITUTE(SUBSTITUTE(SUBSTITUTE(UPPER($L4)," ",""),"F",""),";",REPT(" ",30)),61,30))),0)+IFERROR(VALUE(TRIM(MID(SUBSTITUTE(SUBSTITUTE(SUBSTITUTE(UPPER($L4)," ",""),"F",""),";",REPT(" ",30)),91,30))),0)+IFERROR(VALUE(TRIM(MID(SUBSTITUTE(SUBSTITUTE(SUBSTITUTE(UPPER($L4)," ",""),"F",""),";",REPT(" ",30)),121,30))),0)+IFERROR(VALUE(TRIM(MID(SUBSTITUTE(SUBSTITUTE(SUBSTITUTE(UPPER($L4)," ",""),"F",""),";",REPT(" ",30)),151,30))),0)+IFERROR(VALUE(TRIM(MID(SUBSTITUTE(SUBSTITUTE(SUBSTITUTE(UPPER($L4)," ",""),"F",""),";",REPT(" ",30)),181,30))),0)+IFERROR(VALUE(TRIM(MID(SUBSTITUTE(SUBSTITUTE(SUBSTITUTE(UPPER($L4)," ",""),"F",""),";",REPT(" ",30)),211,30))),0))))) | R4: =IF($C4="","",IF($E4="Falta","-",MAX(0,MIN(10,5+IFERROR(VALUE(TRIM(MID(SUBSTITUTE(SUBSTITUTE(SUBSTITUTE(UPPER($P4)," ",""),"C",""),";",REPT(" ",30)),1,30))),0)+IFERROR(VALUE(TRIM(MID(SUBSTITUTE(SUBSTITUTE(SUBSTITUTE(UPPER($P4)," ",""),"C",""),";",REPT(" ",30)),31,30))),0)+IFERROR(VALUE(TRIM(MID(SUBSTITUTE(SUBSTITUTE(SUBSTITUTE(UPPER($P4)," ",""),"C",""),";",REPT(" ",30)),61,30))),0)+IFERROR(VALUE(TRIM(MID(SUBSTITUTE(SUBSTITUTE(SUBSTITUTE(UPPER($P4)," ",""),"C",""),";",REPT(" ",30)),91,30))),0)+IFERROR(VALUE(TRIM(MID(SUBSTITUTE(SUBSTITUTE(SUBSTITUTE(UPPER($P4)," ",""),"C",""),";",REPT(" ",30)),121,30))),0)+IFERROR(VALUE(TRIM(MID(SUBSTITUTE(SUBSTITUTE(SUBSTITUTE(UPPER($P4)," ",""),"C",""),";",REPT(" ",30)),151,30))),0)+IFERROR(VALUE(TRIM(MID(SUBSTITUTE(SUBSTITUTE(SUBSTITUTE(UPPER($P4)," ",""),"C",""),";",REPT(" ",30)),181,30))),0)+IFERROR(VALUE(TRIM(MID(SUBSTITUTE(SUBSTITUTE(SUBSTITUTE(UPPER($P4)," ",""),"C",""),";",REPT(" ",30)),211,30))),0))))) | V4: =IF($C4="","",IF($E4="Falta","-",MAX(0,MIN(10,5+IFERROR(VALUE(TRIM(MID(SUBSTITUTE(SUBSTITUTE(SUBSTITUTE(UPPER($T4)," ",""),"P",""),";",REPT(" ",30)),1,30))),0)+IFERROR(VALUE(TRIM(MID(SUBSTITUTE(SUBSTITUTE(SUBSTITUTE(UPPER($T4)," ",""),"P",""),";",REPT(" ",30)),31,30))),0)+IFERROR(VALUE(TRIM(MID(SUBSTITUTE(SUBSTITUTE(SUBSTITUTE(UPPER($T4)," ",""),"P",""),";",REPT(" ",30)),61,30))),0)+IFERROR(VALUE(TRIM(MID(SUBSTITUTE(SUBSTITUTE(SUBSTITUTE(UPPER($T4)," ",""),"P",""),";",REPT(" ",30)),91,30))),0)+IFERROR(VALUE(TRIM(MID(SUBSTITUTE(SUBSTITUTE(SUBSTITUTE(UPPER($T4)," ",""),"P",""),";",REPT(" ",30)),121,30))),0)+IFERROR(VALUE(TRIM(MID(SUBSTITUTE(SUBSTITUTE(SUBSTITUTE(UPPER($T4)," ",""),"P",""),";",REPT(" ",30)),151,30))),0)+IFERROR(VALUE(TRIM(MID(SUBSTITUTE(SUBSTITUTE(SUBSTITUTE(UPPER($T4)," ",""),"P",""),";",REPT(" ",30)),181,30))),0)+IFERROR(VALUE(TRIM(MID(SUBSTITUTE(SUBSTITUTE(SUBSTITUTE(UPPER($T4)," ",""),"P",""),";",REPT(" ",30)),211,30))),0)))))
A5: =IF($C5="","",1) | B5: =IF($C5="","","2ª Sessão") | C5: =IF(Preenchimento!$B$10="","",Preenchimento!$B$10) | D5: =IF($C5="","",IF(Preenchimento!$C$10="","-",Preenchimento!$C$10)) | J5: =IF($C5="","",IF($E5="Falta","-",MAX(0,MIN(10,8+IFERROR(VALUE(TRIM(MID(SUBSTITUTE(SUBSTITUTE(SUBSTITUTE(UPPER($H5)," ",""),"D",""),";",REPT(" ",30)),1,30))),0)+IFERROR(VALUE(TRIM(MID(SUBSTITUTE(SUBSTITUTE(SUBSTITUTE(UPPER($H5)," ",""),"D",""),";",REPT(" ",30)),31,30))),0)+IFERROR(VALUE(TRIM(MID(SUBSTITUTE(SUBSTITUTE(SUBSTITUTE(UPPER($H5)," ",""),"D",""),";",REPT(" ",30)),61,30))),0)+IFERROR(VALUE(TRIM(MID(SUBSTITUTE(SUBSTITUTE(SUBSTITUTE(UPPER($H5)," ",""),"D",""),";",REPT(" ",30)),91,30))),0)+IFERROR(VALUE(TRIM(MID(SUBSTITUTE(SUBSTITUTE(SUBSTITUTE(UPPER($H5)," ",""),"D",""),";",REPT(" ",30)),121,30))),0)+IFERROR(VALUE(TRIM(MID(SUBSTITUTE(SUBSTITUTE(SUBSTITUTE(UPPER($H5)," ",""),"D",""),";",REPT(" ",30)),151,30))),0)+IFERROR(VALUE(TRIM(MID(SUBSTITUTE(SUBSTITUTE(SUBSTITUTE(UPPER($H5)," ",""),"D",""),";",REPT(" ",30)),181,30))),0)+IFERROR(VALUE(TRIM(MID(SUBSTITUTE(SUBSTITUTE(SUBSTITUTE(UPPER($H5)," ",""),"D",""),";",REPT(" ",30)),211,30))),0))))) | N5: =IF($C5="","",IF($E5="Falta","-",MAX(0,MIN(10,8+IFERROR(VALUE(TRIM(MID(SUBSTITUTE(SUBSTITUTE(SUBSTITUTE(UPPER($L5)," ",""),"F",""),";",REPT(" ",30)),1,30))),0)+IFERROR(VALUE(TRIM(MID(SUBSTITUTE(SUBSTITUTE(SUBSTITUTE(UPPER($L5)," ",""),"F",""),";",REPT(" ",30)),31,30))),0)+IFERROR(VALUE(TRIM(MID(SUBSTITUTE(SUBSTITUTE(SUBSTITUTE(UPPER($L5)," ",""),"F",""),";",REPT(" ",30)),61,30))),0)+IFERROR(VALUE(TRIM(MID(SUBSTITUTE(SUBSTITUTE(SUBSTITUTE(UPPER($L5)," ",""),"F",""),";",REPT(" ",30)),91,30))),0)+IFERROR(VALUE(TRIM(MID(SUBSTITUTE(SUBSTITUTE(SUBSTITUTE(UPPER($L5)," ",""),"F",""),";",REPT(" ",30)),121,30))),0)+IFERROR(VALUE(TRIM(MID(SUBSTITUTE(SUBSTITUTE(SUBSTITUTE(UPPER($L5)," ",""),"F",""),";",REPT(" ",30)),151,30))),0)+IFERROR(VALUE(TRIM(MID(SUBSTITUTE(SUBSTITUTE(SUBSTITUTE(UPPER($L5)," ",""),"F",""),";",REPT(" ",30)),181,30))),0)+IFERROR(VALUE(TRIM(MID(SUBSTITUTE(SUBSTITUTE(SUBSTITUTE(UPPER($L5)," ",""),"F",""),";",REPT(" ",30)),211,30))),0))))) | R5: =IF($C5="","",IF($E5="Falta","-",MAX(0,MIN(10,5+IFERROR(VALUE(TRIM(MID(SUBSTITUTE(SUBSTITUTE(SUBSTITUTE(UPPER($P5)," ",""),"C",""),";",REPT(" ",30)),1,30))),0)+IFERROR(VALUE(TRIM(MID(SUBSTITUTE(SUBSTITUTE(SUBSTITUTE(UPPER($P5)," ",""),"C",""),";",REPT(" ",30)),31,30))),0)+IFERROR(VALUE(TRIM(MID(SUBSTITUTE(SUBSTITUTE(SUBSTITUTE(UPPER($P5)," ",""),"C",""),";",REPT(" ",30)),61,30))),0)+IFERROR(VALUE(TRIM(MID(SUBSTITUTE(SUBSTITUTE(SUBSTITUTE(UPPER($P5)," ",""),"C",""),";",REPT(" ",30)),91,30))),0)+IFERROR(VALUE(TRIM(MID(SUBSTITUTE(SUBSTITUTE(SUBSTITUTE(UPPER($P5)," ",""),"C",""),";",REPT(" ",30)),121,30))),0)+IFERROR(VALUE(TRIM(MID(SUBSTITUTE(SUBSTITUTE(SUBSTITUTE(UPPER($P5)," ",""),"C",""),";",REPT(" ",30)),151,30))),0)+IFERROR(VALUE(TRIM(MID(SUBSTITUTE(SUBSTITUTE(SUBSTITUTE(UPPER($P5)," ",""),"C",""),";",REPT(" ",30)),181,30))),0)+IFERROR(VALUE(TRIM(MID(SUBSTITUTE(SUBSTITUTE(SUBSTITUTE(UPPER($P5)," ",""),"C",""),";",REPT(" ",30)),211,30))),0))))) | V5: =IF($C5="","",IF($E5="Falta","-",MAX(0,MIN(10,5+IFERROR(VALUE(TRIM(MID(SUBSTITUTE(SUBSTITUTE(SUBSTITUTE(UPPER($T5)," ",""),"P",""),";",REPT(" ",30)),1,30))),0)+IFERROR(VALUE(TRIM(MID(SUBSTITUTE(SUBSTITUTE(SUBSTITUTE(UPPER($T5)," ",""),"P",""),";",REPT(" ",30)),31,30))),0)+IFERROR(VALUE(TRIM(MID(SUBSTITUTE(SUBSTITUTE(SUBSTITUTE(UPPER($T5)," ",""),"P",""),";",REPT(" ",30)),61,30))),0)+IFERROR(VALUE(TRIM(MID(SUBSTITUTE(SUBSTITUTE(SUBSTITUTE(UPPER($T5)," ",""),"P",""),";",REPT(" ",30)),91,30))),0)+IFERROR(VALUE(TRIM(MID(SUBSTITUTE(SUBSTITUTE(SUBSTITUTE(UPPER($T5)," ",""),"P",""),";",REPT(" ",30)),121,30))),0)+IFERROR(VALUE(TRIM(MID(SUBSTITUTE(SUBSTITUTE(SUBSTITUTE(UPPER($T5)," ",""),"P",""),";",REPT(" ",30)),151,30))),0)+IFERROR(VALUE(TRIM(MID(SUBSTITUTE(SUBSTITUTE(SUBSTITUTE(UPPER($T5)," ",""),"P",""),";",REPT(" ",30)),181,30))),0)+IFERROR(VALUE(TRIM(MID(SUBSTITUTE(SUBSTITUTE(SUBSTITUTE(UPPER($T5)," ",""),"P",""),";",REPT(" ",30)),211,30))),0)))))
A6: =IF($C6="","",1) | B6: =IF($C6="","","3ª Sessão") | C6: =IF(Preenchimento!$B$10="","",Preenchimento!$B$10) | D6: =IF($C6="","",IF(Preenchimento!$C$10="","-",Preenchimento!$C$10)) | J6: =IF($C6="","",IF($E6="Falta","-",MAX(0,MIN(10,8+IFERROR(VALUE(TRIM(MID(SUBSTITUTE(SUBSTITUTE(SUBSTITUTE(UPPER($H6)," ",""),"D",""),";",REPT(" ",30)),1,30))),0)+IFERROR(VALUE(TRIM(MID(SUBSTITUTE(SUBSTITUTE(SUBSTITUTE(UPPER($H6)," ",""),"D",""),";",REPT(" ",30)),31,30))),0)+IFERROR(VALUE(TRIM(MID(SUBSTITUTE(SUBSTITUTE(SUBSTITUTE(UPPER($H6)," ",""),"D",""),";",REPT(" ",30)),61,30))),0)+IFERROR(VALUE(TRIM(MID(SUBSTITUTE(SUBSTITUTE(SUBSTITUTE(UPPER($H6)," ",""),"D",""),";",REPT(" ",30)),91,30))),0)+IFERROR(VALUE(TRIM(MID(SUBSTITUTE(SUBSTITUTE(SUBSTITUTE(UPPER($H6)," ",""),"D",""),";",REPT(" ",30)),121,30))),0)+IFERROR(VALUE(TRIM(MID(SUBSTITUTE(SUBSTITUTE(SUBSTITUTE(UPPER($H6)," ",""),"D",""),";",REPT(" ",30)),151,30))),0)+IFERROR(VALUE(TRIM(MID(SUBSTITUTE(SUBSTITUTE(SUBSTITUTE(UPPER($H6)," ",""),"D",""),";",REPT(" ",30)),181,30))),0)+IFERROR(VALUE(TRIM(MID(SUBSTITUTE(SUBSTITUTE(SUBSTITUTE(UPPER($H6)," ",""),"D",""),";",REPT(" ",30)),211,30))),0))))) | N6: =IF($C6="","",IF($E6="Falta","-",MAX(0,MIN(10,8+IFERROR(VALUE(TRIM(MID(SUBSTITUTE(SUBSTITUTE(SUBSTITUTE(UPPER($L6)," ",""),"F",""),";",REPT(" ",30)),1,30))),0)+IFERROR(VALUE(TRIM(MID(SUBSTITUTE(SUBSTITUTE(SUBSTITUTE(UPPER($L6)," ",""),"F",""),";",REPT(" ",30)),31,30))),0)+IFERROR(VALUE(TRIM(MID(SUBSTITUTE(SUBSTITUTE(SUBSTITUTE(UPPER($L6)," ",""),"F",""),";",REPT(" ",30)),61,30))),0)+IFERROR(VALUE(TRIM(MID(SUBSTITUTE(SUBSTITUTE(SUBSTITUTE(UPPER($L6)," ",""),"F",""),";",REPT(" ",30)),91,30))),0)+IFERROR(VALUE(TRIM(MID(SUBSTITUTE(SUBSTITUTE(SUBSTITUTE(UPPER($L6)," ",""),"F",""),";",REPT(" ",30)),121,30))),0)+IFERROR(VALUE(TRIM(MID(SUBSTITUTE(SUBSTITUTE(SUBSTITUTE(UPPER($L6)," ",""),"F",""),";",REPT(" ",30)),151,30))),0)+IFERROR(VALUE(TRIM(MID(SUBSTITUTE(SUBSTITUTE(SUBSTITUTE(UPPER($L6)," ",""),"F",""),";",REPT(" ",30)),181,30))),0)+IFERROR(VALUE(TRIM(MID(SUBSTITUTE(SUBSTITUTE(SUBSTITUTE(UPPER($L6)," ",""),"F",""),";",REPT(" ",30)),211,30))),0))))) | R6: =IF($C6="","",IF($E6="Falta","-",MAX(0,MIN(10,5+IFERROR(VALUE(TRIM(MID(SUBSTITUTE(SUBSTITUTE(SUBSTITUTE(UPPER($P6)," ",""),"C",""),";",REPT(" ",30)),1,30))),0)+IFERROR(VALUE(TRIM(MID(SUBSTITUTE(SUBSTITUTE(SUBSTITUTE(UPPER($P6)," ",""),"C",""),";",REPT(" ",30)),31,30))),0)+IFERROR(VALUE(TRIM(MID(SUBSTITUTE(SUBSTITUTE(SUBSTITUTE(UPPER($P6)," ",""),"C",""),";",REPT(" ",30)),61,30))),0)+IFERROR(VALUE(TRIM(MID(SUBSTITUTE(SUBSTITUTE(SUBSTITUTE(UPPER($P6)," ",""),"C",""),";",REPT(" ",30)),91,30))),0)+IFERROR(VALUE(TRIM(MID(SUBSTITUTE(SUBSTITUTE(SUBSTITUTE(UPPER($P6)," ",""),"C",""),";",REPT(" ",30)),121,30))),0)+IFERROR(VALUE(TRIM(MID(SUBSTITUTE(SUBSTITUTE(SUBSTITUTE(UPPER($P6)," ",""),"C",""),";",REPT(" ",30)),151,30))),0)+IFERROR(VALUE(TRIM(MID(SUBSTITUTE(SUBSTITUTE(SUBSTITUTE(UPPER($P6)," ",""),"C",""),";",REPT(" ",30)),181,30))),0)+IFERROR(VALUE(TRIM(MID(SUBSTITUTE(SUBSTITUTE(SUBSTITUTE(UPPER($P6)," ",""),"C",""),";",REPT(" ",30)),211,30))),0))))) | V6: =IF($C6="","",IF($E6="Falta","-",MAX(0,MIN(10,5+IFERROR(VALUE(TRIM(MID(SUBSTITUTE(SUBSTITUTE(SUBSTITUTE(UPPER($T6)," ",""),"P",""),";",REPT(" ",30)),1,30))),0)+IFERROR(VALUE(TRIM(MID(SUBSTITUTE(SUBSTITUTE(SUBSTITUTE(UPPER($T6)," ",""),"P",""),";",REPT(" ",30)),31,30))),0)+IFERROR(VALUE(TRIM(MID(SUBSTITUTE(SUBSTITUTE(SUBSTITUTE(UPPER($T6)," ",""),"P",""),";",REPT(" ",30)),61,30))),0)+IFERROR(VALUE(TRIM(MID(SUBSTITUTE(SUBSTITUTE(SUBSTITUTE(UPPER($T6)," ",""),"P",""),";",REPT(" ",30)),91,30))),0)+IFERROR(VALUE(TRIM(MID(SUBSTITUTE(SUBSTITUTE(SUBSTITUTE(UPPER($T6)," ",""),"P",""),";",REPT(" ",30)),121,30))),0)+IFERROR(VALUE(TRIM(MID(SUBSTITUTE(SUBSTITUTE(SUBSTITUTE(UPPER($T6)," ",""),"P",""),";",REPT(" ",30)),151,30))),0)+IFERROR(VALUE(TRIM(MID(SUBSTITUTE(SUBSTITUTE(SUBSTITUTE(UPPER($T6)," ",""),"P",""),";",REPT(" ",30)),181,30))),0)+IFERROR(VALUE(TRIM(MID(SUBSTITUTE(SUBSTITUTE(SUBSTITUTE(UPPER($T6)," ",""),"P",""),";",REPT(" ",30)),211,30))),0)))))
A7: =IF($C7="","",1) | B7: =IF($C7="","","4ª Sessão") | C7: =IF(Preenchimento!$B$10="","",Preenchimento!$B$10) | D7: =IF($C7="","",IF(Preenchimento!$C$10="","-",Preenchimento!$C$10)) | J7: =IF($C7="","",IF($E7="Falta","-",MAX(0,MIN(10,8+IFERROR(VALUE(TRIM(MID(SUBSTITUTE(SUBSTITUTE(SUBSTITUTE(UPPER($H7)," ",""),"D",""),";",REPT(" ",30)),1,30))),0)+IFERROR(VALUE(TRIM(MID(SUBSTITUTE(SUBSTITUTE(SUBSTITUTE(UPPER($H7)," ",""),"D",""),";",REPT(" ",30)),31,30))),0)+IFERROR(VALUE(TRIM(MID(SUBSTITUTE(SUBSTITUTE(SUBSTITUTE(UPPER($H7)," ",""),"D",""),";",REPT(" ",30)),61,30))),0)+IFERROR(VALUE(TRIM(MID(SUBSTITUTE(SUBSTITUTE(SUBSTITUTE(UPPER($H7)," ",""),"D",""),";",REPT(" ",30)),91,30))),0)+IFERROR(VALUE(TRIM(MID(SUBSTITUTE(SUBSTITUTE(SUBSTITUTE(UPPER($H7)," ",""),"D",""),";",REPT(" ",30)),121,30))),0)+IFERROR(VALUE(TRIM(MID(SUBSTITUTE(SUBSTITUTE(SUBSTITUTE(UPPER($H7)," ",""),"D",""),";",REPT(" ",30)),151,30))),0)+IFERROR(VALUE(TRIM(MID(SUBSTITUTE(SUBSTITUTE(SUBSTITUTE(UPPER($H7)," ",""),"D",""),";",REPT(" ",30)),181,30))),0)+IFERROR(VALUE(TRIM(MID(SUBSTITUTE(SUBSTITUTE(SUBSTITUTE(UPPER($H7)," ",""),"D",""),";",REPT(" ",30)),211,30))),0))))) | N7: =IF($C7="","",IF($E7="Falta","-",MAX(0,MIN(10,8+IFERROR(VALUE(TRIM(MID(SUBSTITUTE(SUBSTITUTE(SUBSTITUTE(UPPER($L7)," ",""),"F",""),";",REPT(" ",30)),1,30))),0)+IFERROR(VALUE(TRIM(MID(SUBSTITUTE(SUBSTITUTE(SUBSTITUTE(UPPER($L7)," ",""),"F",""),";",REPT(" ",30)),31,30))),0)+IFERROR(VALUE(TRIM(MID(SUBSTITUTE(SUBSTITUTE(SUBSTITUTE(UPPER($L7)," ",""),"F",""),";",REPT(" ",30)),61,30))),0)+IFERROR(VALUE(TRIM(MID(SUBSTITUTE(SUBSTITUTE(SUBSTITUTE(UPPER($L7)," ",""),"F",""),";",REPT(" ",30)),91,30))),0)+IFERROR(VALUE(TRIM(MID(SUBSTITUTE(SUBSTITUTE(SUBSTITUTE(UPPER($L7)," ",""),"F",""),";",REPT(" ",30)),121,30))),0)+IFERROR(VALUE(TRIM(MID(SUBSTITUTE(SUBSTITUTE(SUBSTITUTE(UPPER($L7)," ",""),"F",""),";",REPT(" ",30)),151,30))),0)+IFERROR(VALUE(TRIM(MID(SUBSTITUTE(SUBSTITUTE(SUBSTITUTE(UPPER($L7)," ",""),"F",""),";",REPT(" ",30)),181,30))),0)+IFERROR(VALUE(TRIM(MID(SUBSTITUTE(SUBSTITUTE(SUBSTITUTE(UPPER($L7)," ",""),"F",""),";",REPT(" ",30)),211,30))),0))))) | R7: =IF($C7="","",IF($E7="Falta","-",MAX(0,MIN(10,5+IFERROR(VALUE(TRIM(MID(SUBSTITUTE(SUBSTITUTE(SUBSTITUTE(UPPER($P7)," ",""),"C",""),";",REPT(" ",30)),1,30))),0)+IFERROR(VALUE(TRIM(MID(SUBSTITUTE(SUBSTITUTE(SUBSTITUTE(UPPER($P7)," ",""),"C",""),";",REPT(" ",30)),31,30))),0)+IFERROR(VALUE(TRIM(MID(SUBSTITUTE(SUBSTITUTE(SUBSTITUTE(UPPER($P7)," ",""),"C",""),";",REPT(" ",30)),61,30))),0)+IFERROR(VALUE(TRIM(MID(SUBSTITUTE(SUBSTITUTE(SUBSTITUTE(UPPER($P7)," ",""),"C",""),";",REPT(" ",30)),91,30))),0)+IFERROR(VALUE(TRIM(MID(SUBSTITUTE(SUBSTITUTE(SUBSTITUTE(UPPER($P7)," ",""),"C",""),";",REPT(" ",30)),121,30))),0)+IFERROR(VALUE(TRIM(MID(SUBSTITUTE(SUBSTITUTE(SUBSTITUTE(UPPER($P7)," ",""),"C",""),";",REPT(" ",30)),151,30))),0)+IFERROR(VALUE(TRIM(MID(SUBSTITUTE(SUBSTITUTE(SUBSTITUTE(UPPER($P7)," ",""),"C",""),";",REPT(" ",30)),181,30))),0)+IFERROR(VALUE(TRIM(MID(SUBSTITUTE(SUBSTITUTE(SUBSTITUTE(UPPER($P7)," ",""),"C",""),";",REPT(" ",30)),211,30))),0))))) | V7: =IF($C7="","",IF($E7="Falta","-",MAX(0,MIN(10,5+IFERROR(VALUE(TRIM(MID(SUBSTITUTE(SUBSTITUTE(SUBSTITUTE(UPPER($T7)," ",""),"P",""),";",REPT(" ",30)),1,30))),0)+IFERROR(VALUE(TRIM(MID(SUBSTITUTE(SUBSTITUTE(SUBSTITUTE(UPPER($T7)," ",""),"P",""),";",REPT(" ",30)),31,30))),0)+IFERROR(VALUE(TRIM(MID(SUBSTITUTE(SUBSTITUTE(SUBSTITUTE(UPPER($T7)," ",""),"P",""),";",REPT(" ",30)),61,30))),0)+IFERROR(VALUE(TRIM(MID(SUBSTITUTE(SUBSTITUTE(SUBSTITUTE(UPPER($T7)," ",""),"P",""),";",REPT(" ",30)),91,30))),0)+IFERROR(VALUE(TRIM(MID(SUBSTITUTE(SUBSTITUTE(SUBSTITUTE(UPPER($T7)," ",""),"P",""),";",REPT(" ",30)),121,30))),0)+IFERROR(VALUE(TRIM(MID(SUBSTITUTE(SUBSTITUTE(SUBSTITUTE(UPPER($T7)," ",""),"P",""),";",REPT(" ",30)),151,30))),0)+IFERROR(VALUE(TRIM(MID(SUBSTITUTE(SUBSTITUTE(SUBSTITUTE(UPPER($T7)," ",""),"P",""),";",REPT(" ",30)),181,30))),0)+IFERROR(VALUE(TRIM(MID(SUBSTITUTE(SUBSTITUTE(SUBSTITUTE(UPPER($T7)," ",""),"P",""),";",REPT(" ",30)),211,30))),0)))))
A8: =IF($C8="","",1) | B8: =IF($C8="","","5ª Sessão") | C8: =IF(Preenchimento!$B$10="","",Preenchimento!$B$10) | D8: =IF($C8="","",IF(Preenchimento!$C$10="","-",Preenchimento!$C$10)) | J8: =IF($C8="","",IF($E8="Falta","-",MAX(0,MIN(10,8+IFERROR(VALUE(TRIM(MID(SUBSTITUTE(SUBSTITUTE(SUBSTITUTE(UPPER($H8)," ",""),"D",""),";",REPT(" ",30)),1,30))),0)+IFERROR(VALUE(TRIM(MID(SUBSTITUTE(SUBSTITUTE(SUBSTITUTE(UPPER($H8)," ",""),"D",""),";",REPT(" ",30)),31,30))),0)+IFERROR(VALUE(TRIM(MID(SUBSTITUTE(SUBSTITUTE(SUBSTITUTE(UPPER($H8)," ",""),"D",""),";",REPT(" ",30)),61,30))),0)+IFERROR(VALUE(TRIM(MID(SUBSTITUTE(SUBSTITUTE(SUBSTITUTE(UPPER($H8)," ",""),"D",""),";",REPT(" ",30)),91,30))),0)+IFERROR(VALUE(TRIM(MID(SUBSTITUTE(SUBSTITUTE(SUBSTITUTE(UPPER($H8)," ",""),"D",""),";",REPT(" ",30)),121,30))),0)+IFERROR(VALUE(TRIM(MID(SUBSTITUTE(SUBSTITUTE(SUBSTITUTE(UPPER($H8)," ",""),"D",""),";",REPT(" ",30)),151,30))),0)+IFERROR(VALUE(TRIM(MID(SUBSTITUTE(SUBSTITUTE(SUBSTITUTE(UPPER($H8)," ",""),"D",""),";",REPT(" ",30)),181,30))),0)+IFERROR(VALUE(TRIM(MID(SUBSTITUTE(SUBSTITUTE(SUBSTITUTE(UPPER($H8)," ",""),"D",""),";",REPT(" ",30)),211,30))),0))))) | N8: =IF($C8="","",IF($E8="Falta","-",MAX(0,MIN(10,8+IFERROR(VALUE(TRIM(MID(SUBSTITUTE(SUBSTITUTE(SUBSTITUTE(UPPER($L8)," ",""),"F",""),";",REPT(" ",30)),1,30))),0)+IFERROR(VALUE(TRIM(MID(SUBSTITUTE(SUBSTITUTE(SUBSTITUTE(UPPER($L8)," ",""),"F",""),";",REPT(" ",30)),31,30))),0)+IFERROR(VALUE(TRIM(MID(SUBSTITUTE(SUBSTITUTE(SUBSTITUTE(UPPER($L8)," ",""),"F",""),";",REPT(" ",30)),61,30))),0)+IFERROR(VALUE(TRIM(MID(SUBSTITUTE(SUBSTITUTE(SUBSTITUTE(UPPER($L8)," ",""),"F",""),";",REPT(" ",30)),91,30))),0)+IFERROR(VALUE(TRIM(MID(SUBSTITUTE(SUBSTITUTE(SUBSTITUTE(UPPER($L8)," ",""),"F",""),";",REPT(" ",30)),121,30))),0)+IFERROR(VALUE(TRIM(MID(SUBSTITUTE(SUBSTITUTE(SUBSTITUTE(UPPER($L8)," ",""),"F",""),";",REPT(" ",30)),151,30))),0)+IFERROR(VALUE(TRIM(MID(SUBSTITUTE(SUBSTITUTE(SUBSTITUTE(UPPER($L8)," ",""),"F",""),";",REPT(" ",30)),181,30))),0)+IFERROR(VALUE(TRIM(MID(SUBSTITUTE(SUBSTITUTE(SUBSTITUTE(UPPER($L8)," ",""),"F",""),";",REPT(" ",30)),211,30))),0))))) | R8: =IF($C8="","",IF($E8="Falta","-",MAX(0,MIN(10,5+IFERROR(VALUE(TRIM(MID(SUBSTITUTE(SUBSTITUTE(SUBSTITUTE(UPPER($P8)," ",""),"C",""),";",REPT(" ",30)),1,30))),0)+IFERROR(VALUE(TRIM(MID(SUBSTITUTE(SUBSTITUTE(SUBSTITUTE(UPPER($P8)," ",""),"C",""),";",REPT(" ",30)),31,30))),0)+IFERROR(VALUE(TRIM(MID(SUBSTITUTE(SUBSTITUTE(SUBSTITUTE(UPPER($P8)," ",""),"C",""),";",REPT(" ",30)),61,30))),0)+IFERROR(VALUE(TRIM(MID(SUBSTITUTE(SUBSTITUTE(SUBSTITUTE(UPPER($P8)," ",""),"C",""),";",REPT(" ",30)),91,30))),0)+IFERROR(VALUE(TRIM(MID(SUBSTITUTE(SUBSTITUTE(SUBSTITUTE(UPPER($P8)," ",""),"C",""),";",REPT(" ",30)),121,30))),0)+IFERROR(VALUE(TRIM(MID(SUBSTITUTE(SUBSTITUTE(SUBSTITUTE(UPPER($P8)," ",""),"C",""),";",REPT(" ",30)),151,30))),0)+IFERROR(VALUE(TRIM(MID(SUBSTITUTE(SUBSTITUTE(SUBSTITUTE(UPPER($P8)," ",""),"C",""),";",REPT(" ",30)),181,30))),0)+IFERROR(VALUE(TRIM(MID(SUBSTITUTE(SUBSTITUTE(SUBSTITUTE(UPPER($P8)," ",""),"C",""),";",REPT(" ",30)),211,30))),0))))) | V8: =IF($C8="","",IF($E8="Falta","-",MAX(0,MIN(10,5+IFERROR(VALUE(TRIM(MID(SUBSTITUTE(SUBSTITUTE(SUBSTITUTE(UPPER($T8)," ",""),"P",""),";",REPT(" ",30)),1,30))),0)+IFERROR(VALUE(TRIM(MID(SUBSTITUTE(SUBSTITUTE(SUBSTITUTE(UPPER($T8)," ",""),"P",""),";",REPT(" ",30)),31,30))),0)+IFERROR(VALUE(TRIM(MID(SUBSTITUTE(SUBSTITUTE(SUBSTITUTE(UPPER($T8)," ",""),"P",""),";",REPT(" ",30)),61,30))),0)+IFERROR(VALUE(TRIM(MID(SUBSTITUTE(SUBSTITUTE(SUBSTITUTE(UPPER($T8)," ",""),"P",""),";",REPT(" ",30)),91,30))),0)+IFERROR(VALUE(TRIM(MID(SUBSTITUTE(SUBSTITUTE(SUBSTITUTE(UPPER($T8)," ",""),"P",""),";",REPT(" ",30)),121,30))),0)+IFERROR(VALUE(TRIM(MID(SUBSTITUTE(SUBSTITUTE(SUBSTITUTE(UPPER($T8)," ",""),"P",""),";",REPT(" ",30)),151,30))),0)+IFERROR(VALUE(TRIM(MID(SUBSTITUTE(SUBSTITUTE(SUBSTITUTE(UPPER($T8)," ",""),"P",""),";",REPT(" ",30)),181,30))),0)+IFERROR(VALUE(TRIM(MID(SUBSTITUTE(SUBSTITUTE(SUBSTITUTE(UPPER($T8)," ",""),"P",""),";",REPT(" ",30)),211,30))),0)))))
A9: =IF($C9="","",2) | B9: =IF($C9="","","1ª Sessão") | C9: =IF(Preenchimento!$B$11="","",Preenchimento!$B$11) | D9: =IF($C9="","",IF(Preenchimento!$C$11="","-",Preenchimento!$C$11)) | J9: =IF($C9="","",IF($E9="Falta","-",MAX(0,MIN(10,8+IFERROR(VALUE(TRIM(MID(SUBSTITUTE(SUBSTITUTE(SUBSTITUTE(UPPER($H9)," ",""),"D",""),";",REPT(" ",30)),1,30))),0)+IFERROR(VALUE(TRIM(MID(SUBSTITUTE(SUBSTITUTE(SUBSTITUTE(UPPER($H9)," ",""),"D",""),";",REPT(" ",30)),31,30))),0)+IFERROR(VALUE(TRIM(MID(SUBSTITUTE(SUBSTITUTE(SUBSTITUTE(UPPER($H9)," ",""),"D",""),";",REPT(" ",30)),61,30))),0)+IFERROR(VALUE(TRIM(MID(SUBSTITUTE(SUBSTITUTE(SUBSTITUTE(UPPER($H9)," ",""),"D",""),";",REPT(" ",30)),91,30))),0)+IFERROR(VALUE(TRIM(MID(SUBSTITUTE(SUBSTITUTE(SUBSTITUTE(UPPER($H9)," ",""),"D",""),";",REPT(" ",30)),121,30))),0)+IFERROR(VALUE(TRIM(MID(SUBSTITUTE(SUBSTITUTE(SUBSTITUTE(UPPER($H9)," ",""),"D",""),";",REPT(" ",30)),151,30))),0)+IFERROR(VALUE(TRIM(MID(SUBSTITUTE(SUBSTITUTE(SUBSTITUTE(UPPER($H9)," ",""),"D",""),";",REPT(" ",30)),181,30))),0)+IFERROR(VALUE(TRIM(MID(SUBSTITUTE(SUBSTITUTE(SUBSTITUTE(UPPER($H9)," ",""),"D",""),";",REPT(" ",30)),211,30))),0))))) | N9: =IF($C9="","",IF($E9="Falta","-",MAX(0,MIN(10,8+IFERROR(VALUE(TRIM(MID(SUBSTITUTE(SUBSTITUTE(SUBSTITUTE(UPPER($L9)," ",""),"F",""),";",REPT(" ",30)),1,30))),0)+IFERROR(VALUE(TRIM(MID(SUBSTITUTE(SUBSTITUTE(SUBSTITUTE(UPPER($L9)," ",""),"F",""),";",REPT(" ",30)),31,30))),0)+IFERROR(VALUE(TRIM(MID(SUBSTITUTE(SUBSTITUTE(SUBSTITUTE(UPPER($L9)," ",""),"F",""),";",REPT(" ",30)),61,30))),0)+IFERROR(VALUE(TRIM(MID(SUBSTITUTE(SUBSTITUTE(SUBSTITUTE(UPPER($L9)," ",""),"F",""),";",REPT(" ",30)),91,30))),0)+IFERROR(VALUE(TRIM(MID(SUBSTITUTE(SUBSTITUTE(SUBSTITUTE(UPPER($L9)," ",""),"F",""),";",REPT(" ",30)),121,30))),0)+IFERROR(VALUE(TRIM(MID(SUBSTITUTE(SUBSTITUTE(SUBSTITUTE(UPPER($L9)," ",""),"F",""),";",REPT(" ",30)),151,30))),0)+IFERROR(VALUE(TRIM(MID(SUBSTITUTE(SUBSTITUTE(SUBSTITUTE(UPPER($L9)," ",""),"F",""),";",REPT(" ",30)),181,30))),0)+IFERROR(VALUE(TRIM(MID(SUBSTITUTE(SUBSTITUTE(SUBSTITUTE(UPPER($L9)," ",""),"F",""),";",REPT(" ",30)),211,30))),0))))) | R9: =IF($C9="","",IF($E9="Falta","-",MAX(0,MIN(10,5+IFERROR(VALUE(TRIM(MID(SUBSTITUTE(SUBSTITUTE(SUBSTITUTE(UPPER($P9)," ",""),"C",""),";",REPT(" ",30)),1,30))),0)+IFERROR(VALUE(TRIM(MID(SUBSTITUTE(SUBSTITUTE(SUBSTITUTE(UPPER($P9)," ",""),"C",""),";",REPT(" ",30)),31,30))),0)+IFERROR(VALUE(TRIM(MID(SUBSTITUTE(SUBSTITUTE(SUBSTITUTE(UPPER($P9)," ",""),"C",""),";",REPT(" ",30)),61,30))),0)+IFERROR(VALUE(TRIM(MID(SUBSTITUTE(SUBSTITUTE(SUBSTITUTE(UPPER($P9)," ",""),"C",""),";",REPT(" ",30)),91,30))),0)+IFERROR(VALUE(TRIM(MID(SUBSTITUTE(SUBSTITUTE(SUBSTITUTE(UPPER($P9)," ",""),"C",""),";",REPT(" ",30)),121,30))),0)+IFERROR(VALUE(TRIM(MID(SUBSTITUTE(SUBSTITUTE(SUBSTITUTE(UPPER($P9)," ",""),"C",""),";",REPT(" ",30)),151,30))),0)+IFERROR(VALUE(TRIM(MID(SUBSTITUTE(SUBSTITUTE(SUBSTITUTE(UPPER($P9)," ",""),"C",""),";",REPT(" ",30)),181,30))),0)+IFERROR(VALUE(TRIM(MID(SUBSTITUTE(SUBSTITUTE(SUBSTITUTE(UPPER($P9)," ",""),"C",""),";",REPT(" ",30)),211,30))),0))))) | V9: =IF($C9="","",IF($E9="Falta","-",MAX(0,MIN(10,5+IFERROR(VALUE(TRIM(MID(SUBSTITUTE(SUBSTITUTE(SUBSTITUTE(UPPER($T9)," ",""),"P",""),";",REPT(" ",30)),1,30))),0)+IFERROR(VALUE(TRIM(MID(SUBSTITUTE(SUBSTITUTE(SUBSTITUTE(UPPER($T9)," ",""),"P",""),";",REPT(" ",30)),31,30))),0)+IFERROR(VALUE(TRIM(MID(SUBSTITUTE(SUBSTITUTE(SUBSTITUTE(UPPER($T9)," ",""),"P",""),";",REPT(" ",30)),61,30))),0)+IFERROR(VALUE(TRIM(MID(SUBSTITUTE(SUBSTITUTE(SUBSTITUTE(UPPER($T9)," ",""),"P",""),";",REPT(" ",30)),91,30))),0)+IFERROR(VALUE(TRIM(MID(SUBSTITUTE(SUBSTITUTE(SUBSTITUTE(UPPER($T9)," ",""),"P",""),";",REPT(" ",30)),121,30))),0)+IFERROR(VALUE(TRIM(MID(SUBSTITUTE(SUBSTITUTE(SUBSTITUTE(UPPER($T9)," ",""),"P",""),";",REPT(" ",30)),151,30))),0)+IFERROR(VALUE(TRIM(MID(SUBSTITUTE(SUBSTITUTE(SUBSTITUTE(UPPER($T9)," ",""),"P",""),";",REPT(" ",30)),181,30))),0)+IFERROR(VALUE(TRIM(MID(SUBSTITUTE(SUBSTITUTE(SUBSTITUTE(UPPER($T9)," ",""),"P",""),";",REPT(" ",30)),211,30))),0)))))
A10: =IF($C10="","",2) | B10: =IF($C10="","","2ª Sessão") | C10: =IF(Preenchimento!$B$11="","",Preenchimento!$B$11) | D10: =IF($C10="","",IF(Preenchimento!$C$11="","-",Preenchimento!$C$11)) | J10: =IF($C10="","",IF($E10="Falta","-",MAX(0,MIN(10,8+IFERROR(VALUE(TRIM(MID(SUBSTITUTE(SUBSTITUTE(SUBSTITUTE(UPPER($H10)," ",""),"D",""),";",REPT(" ",30)),1,30))),0)+IFERROR(VALUE(TRIM(MID(SUBSTITUTE(SUBSTITUTE(SUBSTITUTE(UPPER($H10)," ",""),"D",""),";",REPT(" ",30)),31,30))),0)+IFERROR(VALUE(TRIM(MID(SUBSTITUTE(SUBSTITUTE(SUBSTITUTE(UPPER($H10)," ",""),"D",""),";",REPT(" ",30)),61,30))),0)+IFERROR(VALUE(TRIM(MID(SUBSTITUTE(SUBSTITUTE(SUBSTITUTE(UPPER($H10)," ",""),"D",""),";",REPT(" ",30)),91,30))),0)+IFERROR(VALUE(TRIM(MID(SUBSTITUTE(SUBSTITUTE(SUBSTITUTE(UPPER($H10)," ",""),"D",""),";",REPT(" ",30)),121,30))),0)+IFERROR(VALUE(TRIM(MID(SUBSTITUTE(SUBSTITUTE(SUBSTITUTE(UPPER($H10)," ",""),"D",""),";",REPT(" ",30)),151,30))),0)+IFERROR(VALUE(TRIM(MID(SUBSTITUTE(SUBSTITUTE(SUBSTITUTE(UPPER($H10)," ",""),"D",""),";",REPT(" ",30)),181,30))),0)+IFERROR(VALUE(TRIM(MID(SUBSTITUTE(SUBSTITUTE(SUBSTITUTE(UPPER($H10)," ",""),"D",""),";",REPT(" ",30)),211,30))),0))))) | N10: =IF($C10="","",IF($E10="Falta","-",MAX(0,MIN(10,8+IFERROR(VALUE(TRIM(MID(SUBSTITUTE(SUBSTITUTE(SUBSTITUTE(UPPER($L10)," ",""),"F",""),";",REPT(" ",30)),1,30))),0)+IFERROR(VALUE(TRIM(MID(SUBSTITUTE(SUBSTITUTE(SUBSTITUTE(UPPER($L10)," ",""),"F",""),";",REPT(" ",30)),31,30))),0)+IFERROR(VALUE(TRIM(MID(SUBSTITUTE(SUBSTITUTE(SUBSTITUTE(UPPER($L10)," ",""),"F",""),";",REPT(" ",30)),61,30))),0)+IFERROR(VALUE(TRIM(MID(SUBSTITUTE(SUBSTITUTE(SUBSTITUTE(UPPER($L10)," ",""),"F",""),";",REPT(" ",30)),91,30))),0)+IFERROR(VALUE(TRIM(MID(SUBSTITUTE(SUBSTITUTE(SUBSTITUTE(UPPER($L10)," ",""),"F",""),";",REPT(" ",30)),121,30))),0)+IFERROR(VALUE(TRIM(MID(SUBSTITUTE(SUBSTITUTE(SUBSTITUTE(UPPER($L10)," ",""),"F",""),";",REPT(" ",30)),151,30))),0)+IFERROR(VALUE(TRIM(MID(SUBSTITUTE(SUBSTITUTE(SUBSTITUTE(UPPER($L10)," ",""),"F",""),";",REPT(" ",30)),181,30))),0)+IFERROR(VALUE(TRIM(MID(SUBSTITUTE(SUBSTITUTE(SUBSTITUTE(UPPER($L10)," ",""),"F",""),";",REPT(" ",30)),211,30))),0))))) | R10: =IF($C10="","",IF($E10="Falta","-",MAX(0,MIN(10,5+IFERROR(VALUE(TRIM(MID(SUBSTITUTE(SUBSTITUTE(SUBSTITUTE(UPPER($P10)," ",""),"C",""),";",REPT(" ",30)),1,30))),0)+IFERROR(VALUE(TRIM(MID(SUBSTITUTE(SUBSTITUTE(SUBSTITUTE(UPPER($P10)," ",""),"C",""),";",REPT(" ",30)),31,30))),0)+IFERROR(VALUE(TRIM(MID(SUBSTITUTE(SUBSTITUTE(SUBSTITUTE(UPPER($P10)," ",""),"C",""),";",REPT(" ",30)),61,30))),0)+IFERROR(VALUE(TRIM(MID(SUBSTITUTE(SUBSTITUTE(SUBSTITUTE(UPPER($P10)," ",""),"C",""),";",REPT(" ",30)),91,30))),0)+IFERROR(VALUE(TRIM(MID(SUBSTITUTE(SUBSTITUTE(SUBSTITUTE(UPPER($P10)," ",""),"C",""),";",REPT(" ",30)),121,30))),0)+IFERROR(VALUE(TRIM(MID(SUBSTITUTE(SUBSTITUTE(SUBSTITUTE(UPPER($P10)," ",""),"C",""),";",REPT(" ",30)),151,30))),0)+IFERROR(VALUE(TRIM(MID(SUBSTITUTE(SUBSTITUTE(SUBSTITUTE(UPPER($P10)," ",""),"C",""),";",REPT(" ",30)),181,30))),0)+IFERROR(VALUE(TRIM(MID(SUBSTITUTE(SUBSTITUTE(SUBSTITUTE(UPPER($P10)," ",""),"C",""),";",REPT(" ",30)),211,30))),0))))) | V10: =IF($C10="","",IF($E10="Falta","-",MAX(0,MIN(10,5+IFERROR(VALUE(TRIM(MID(SUBSTITUTE(SUBSTITUTE(SUBSTITUTE(UPPER($T10)," ",""),"P",""),";",REPT(" ",30)),1,30))),0)+IFERROR(VALUE(TRIM(MID(SUBSTITUTE(SUBSTITUTE(SUBSTITUTE(UPPER($T10)," ",""),"P",""),";",REPT(" ",30)),31,30))),0)+IFERROR(VALUE(TRIM(MID(SUBSTITUTE(SUBSTITUTE(SUBSTITUTE(UPPER($T10)," ",""),"P",""),";",REPT(" ",30)),61,30))),0)+IFERROR(VALUE(TRIM(MID(SUBSTITUTE(SUBSTITUTE(SUBSTITUTE(UPPER($T10)," ",""),"P",""),";",REPT(" ",30)),91,30))),0)+IFERROR(VALUE(TRIM(MID(SUBSTITUTE(SUBSTITUTE(SUBSTITUTE(UPPER($T10)," ",""),"P",""),";",REPT(" ",30)),121,30))),0)+IFERROR(VALUE(TRIM(MID(SUBSTITUTE(SUBSTITUTE(SUBSTITUTE(UPPER($T10)," ",""),"P",""),";",REPT(" ",30)),151,30))),0)+IFERROR(VALUE(TRIM(MID(SUBSTITUTE(SUBSTITUTE(SUBSTITUTE(UPPER($T10)," ",""),"P",""),";",REPT(" ",30)),181,30))),0)+IFERROR(VALUE(TRIM(MID(SUBSTITUTE(SUBSTITUTE(SUBSTITUTE(UPPER($T10)," ",""),"P",""),";",REPT(" ",30)),211,30))),0)))))
A11: =IF($C11="","",2) | B11: =IF($C11="","","3ª Sessão") | C11: =IF(Preenchimento!$B$11="","",Preenchimento!$B$11) | D11: =IF($C11="","",IF(Preenchimento!$C$11="","-",Preenchimento!$C$11)) | J11: =IF($C11="","",IF($E11="Falta","-",MAX(0,MIN(10,8+IFERROR(VALUE(TRIM(MID(SUBSTITUTE(SUBSTITUTE(SUBSTITUTE(UPPER($H11)," ",""),"D",""),";",REPT(" ",30)),1,30))),0)+IFERROR(VALUE(TRIM(MID(SUBSTITUTE(SUBSTITUTE(SUBSTITUTE(UPPER($H11)," ",""),"D",""),";",REPT(" ",30)),31,30))),0)+IFERROR(VALUE(TRIM(MID(SUBSTITUTE(SUBSTITUTE(SUBSTITUTE(UPPER($H11)," ",""),"D",""),";",REPT(" ",30)),61,30))),0)+IFERROR(VALUE(TRIM(MID(SUBSTITUTE(SUBSTITUTE(SUBSTITUTE(UPPER($H11)," ",""),"D",""),";",REPT(" ",30)),91,30))),0)+IFERROR(VALUE(TRIM(MID(SUBSTITUTE(SUBSTITUTE(SUBSTITUTE(UPPER($H11)," ",""),"D",""),";",REPT(" ",30)),121,30))),0)+IFERROR(VALUE(TRIM(MID(SUBSTITUTE(SUBSTITUTE(SUBSTITUTE(UPPER($H11)," ",""),"D",""),";",REPT(" ",30)),151,30))),0)+IFERROR(VALUE(TRIM(MID(SUBSTITUTE(SUBSTITUTE(SUBSTITUTE(UPPER($H11)," ",""),"D",""),";",REPT(" ",30)),181,30))),0)+IFERROR(VALUE(TRIM(MID(SUBSTITUTE(SUBSTITUTE(SUBSTITUTE(UPPER($H11)," ",""),"D",""),";",REPT(" ",30)),211,30))),0))))) | N11: =IF($C11="","",IF($E11="Falta","-",MAX(0,MIN(10,8+IFERROR(VALUE(TRIM(MID(SUBSTITUTE(SUBSTITUTE(SUBSTITUTE(UPPER($L11)," ",""),"F",""),";",REPT(" ",30)),1,30))),0)+IFERROR(VALUE(TRIM(MID(SUBSTITUTE(SUBSTITUTE(SUBSTITUTE(UPPER($L11)," ",""),"F",""),";",REPT(" ",30)),31,30))),0)+IFERROR(VALUE(TRIM(MID(SUBSTITUTE(SUBSTITUTE(SUBSTITUTE(UPPER($L11)," ",""),"F",""),";",REPT(" ",30)),61,30))),0)+IFERROR(VALUE(TRIM(MID(SUBSTITUTE(SUBSTITUTE(SUBSTITUTE(UPPER($L11)," ",""),"F",""),";",REPT(" ",30)),91,30))),0)+IFERROR(VALUE(TRIM(MID(SUBSTITUTE(SUBSTITUTE(SUBSTITUTE(UPPER($L11)," ",""),"F",""),";",REPT(" ",30)),121,30))),0)+IFERROR(VALUE(TRIM(MID(SUBSTITUTE(SUBSTITUTE(SUBSTITUTE(UPPER($L11)," ",""),"F",""),";",REPT(" ",30)),151,30))),0)+IFERROR(VALUE(TRIM(MID(SUBSTITUTE(SUBSTITUTE(SUBSTITUTE(UPPER($L11)," ",""),"F",""),";",REPT(" ",30)),181,30))),0)+IFERROR(VALUE(TRIM(MID(SUBSTITUTE(SUBSTITUTE(SUBSTITUTE(UPPER($L11)," ",""),"F",""),";",REPT(" ",30)),211,30))),0))))) | R11: =IF($C11="","",IF($E11="Falta","-",MAX(0,MIN(10,5+IFERROR(VALUE(TRIM(MID(SUBSTITUTE(SUBSTITUTE(SUBSTITUTE(UPPER($P11)," ",""),"C",""),";",REPT(" ",30)),1,30))),0)+IFERROR(VALUE(TRIM(MID(SUBSTITUTE(SUBSTITUTE(SUBSTITUTE(UPPER($P11)," ",""),"C",""),";",REPT(" ",30)),31,30))),0)+IFERROR(VALUE(TRIM(MID(SUBSTITUTE(SUBSTITUTE(SUBSTITUTE(UPPER($P11)," ",""),"C",""),";",REPT(" ",30)),61,30))),0)+IFERROR(VALUE(TRIM(MID(SUBSTITUTE(SUBSTITUTE(SUBSTITUTE(UPPER($P11)," ",""),"C",""),";",REPT(" ",30)),91,30))),0)+IFERROR(VALUE(TRIM(MID(SUBSTITUTE(SUBSTITUTE(SUBSTITUTE(UPPER($P11)," ",""),"C",""),";",REPT(" ",30)),121,30))),0)+IFERROR(VALUE(TRIM(MID(SUBSTITUTE(SUBSTITUTE(SUBSTITUTE(UPPER($P11)," ",""),"C",""),";",REPT(" ",30)),151,30))),0)+IFERROR(VALUE(TRIM(MID(SUBSTITUTE(SUBSTITUTE(SUBSTITUTE(UPPER($P11)," ",""),"C",""),";",REPT(" ",30)),181,30))),0)+IFERROR(VALUE(TRIM(MID(SUBSTITUTE(SUBSTITUTE(SUBSTITUTE(UPPER($P11)," ",""),"C",""),";",REPT(" ",30)),211,30))),0))))) | V11: =IF($C11="","",IF($E11="Falta","-",MAX(0,MIN(10,5+IFERROR(VALUE(TRIM(MID(SUBSTITUTE(SUBSTITUTE(SUBSTITUTE(UPPER($T11)," ",""),"P",""),";",REPT(" ",30)),1,30))),0)+IFERROR(VALUE(TRIM(MID(SUBSTITUTE(SUBSTITUTE(SUBSTITUTE(UPPER($T11)," ",""),"P",""),";",REPT(" ",30)),31,30))),0)+IFERROR(VALUE(TRIM(MID(SUBSTITUTE(SUBSTITUTE(SUBSTITUTE(UPPER($T11)," ",""),"P",""),";",REPT(" ",30)),61,30))),0)+IFERROR(VALUE(TRIM(MID(SUBSTITUTE(SUBSTITUTE(SUBSTITUTE(UPPER($T11)," ",""),"P",""),";",REPT(" ",30)),91,30))),0)+IFERROR(VALUE(TRIM(MID(SUBSTITUTE(SUBSTITUTE(SUBSTITUTE(UPPER($T11)," ",""),"P",""),";",REPT(" ",30)),121,30))),0)+IFERROR(VALUE(TRIM(MID(SUBSTITUTE(SUBSTITUTE(SUBSTITUTE(UPPER($T11)," ",""),"P",""),";",REPT(" ",30)),151,30))),0)+IFERROR(VALUE(TRIM(MID(SUBSTITUTE(SUBSTITUTE(SUBSTITUTE(UPPER($T11)," ",""),"P",""),";",REPT(" ",30)),181,30))),0)+IFERROR(VALUE(TRIM(MID(SUBSTITUTE(SUBSTITUTE(SUBSTITUTE(UPPER($T11)," ",""),"P",""),";",REPT(" ",30)),211,30))),0)))))
A12: =IF($C12="","",2) | B12: =IF($C12="","","4ª Sessão") | C12: =IF(Preenchimento!$B$11="","",Preenchimento!$B$11) | D12: =IF($C12="","",IF(Preenchimento!$C$11="","-",Preenchimento!$C$11)) | J12: =IF($C12="","",IF($E12="Falta","-",MAX(0,MIN(10,8+IFERROR(VALUE(TRIM(MID(SUBSTITUTE(SUBSTITUTE(SUBSTITUTE(UPPER($H12)," ",""),"D",""),";",REPT(" ",30)),1,30))),0)+IFERROR(VALUE(TRIM(MID(SUBSTITUTE(SUBSTITUTE(SUBSTITUTE(UPPER($H12)," ",""),"D",""),";",REPT(" ",30)),31,30))),0)+IFERROR(VALUE(TRIM(MID(SUBSTITUTE(SUBSTITUTE(SUBSTITUTE(UPPER($H12)," ",""),"D",""),";",REPT(" ",30)),61,30))),0)+IFERROR(VALUE(TRIM(MID(SUBSTITUTE(SUBSTITUTE(SUBSTITUTE(UPPER($H12)," ",""),"D",""),";",REPT(" ",30)),91,30))),0)+IFERROR(VALUE(TRIM(MID(SUBSTITUTE(SUBSTITUTE(SUBSTITUTE(UPPER($H12)," ",""),"D",""),";",REPT(" ",30)),121,30))),0)+IFERROR(VALUE(TRIM(MID(SUBSTITUTE(SUBSTITUTE(SUBSTITUTE(UPPER($H12)," ",""),"D",""),";",REPT(" ",30)),151,30))),0)+IFERROR(VALUE(TRIM(MID(SUBSTITUTE(SUBSTITUTE(SUBSTITUTE(UPPER($H12)," ",""),"D",""),";",REPT(" ",30)),181,30))),0)+IFERROR(VALUE(TRIM(MID(SUBSTITUTE(SUBSTITUTE(SUBSTITUTE(UPPER($H12)," ",""),"D",""),";",REPT(" ",30)),211,30))),0))))) | N12: =IF($C12="","",IF($E12="Falta","-",MAX(0,MIN(10,8+IFERROR(VALUE(TRIM(MID(SUBSTITUTE(SUBSTITUTE(SUBSTITUTE(UPPER($L12)," ",""),"F",""),";",REPT(" ",30)),1,30))),0)+IFERROR(VALUE(TRIM(MID(SUBSTITUTE(SUBSTITUTE(SUBSTITUTE(UPPER($L12)," ",""),"F",""),";",REPT(" ",30)),31,30))),0)+IFERROR(VALUE(TRIM(MID(SUBSTITUTE(SUBSTITUTE(SUBSTITUTE(UPPER($L12)," ",""),"F",""),";",REPT(" ",30)),61,30))),0)+IFERROR(VALUE(TRIM(MID(SUBSTITUTE(SUBSTITUTE(SUBSTITUTE(UPPER($L12)," ",""),"F",""),";",REPT(" ",30)),91,30))),0)+IFERROR(VALUE(TRIM(MID(SUBSTITUTE(SUBSTITUTE(SUBSTITUTE(UPPER($L12)," ",""),"F",""),";",REPT(" ",30)),121,30))),0)+IFERROR(VALUE(TRIM(MID(SUBSTITUTE(SUBSTITUTE(SUBSTITUTE(UPPER($L12)," ",""),"F",""),";",REPT(" ",30)),151,30))),0)+IFERROR(VALUE(TRIM(MID(SUBSTITUTE(SUBSTITUTE(SUBSTITUTE(UPPER($L12)," ",""),"F",""),";",REPT(" ",30)),181,30))),0)+IFERROR(VALUE(TRIM(MID(SUBSTITUTE(SUBSTITUTE(SUBSTITUTE(UPPER($L12)," ",""),"F",""),";",REPT(" ",30)),211,30))),0))))) | R12: =IF($C12="","",IF($E12="Falta","-",MAX(0,MIN(10,5+IFERROR(VALUE(TRIM(MID(SUBSTITUTE(SUBSTITUTE(SUBSTITUTE(UPPER($P12)," ",""),"C",""),";",REPT(" ",30)),1,30))),0)+IFERROR(VALUE(TRIM(MID(SUBSTITUTE(SUBSTITUTE(SUBSTITUTE(UPPER($P12)," ",""),"C",""),";",REPT(" ",30)),31,30))),0)+IFERROR(VALUE(TRIM(MID(SUBSTITUTE(SUBSTITUTE(SUBSTITUTE(UPPER($P12)," ",""),"C",""),";",REPT(" ",30)),61,30))),0)+IFERROR(VALUE(TRIM(MID(SUBSTITUTE(SUBSTITUTE(SUBSTITUTE(UPPER($P12)," ",""),"C",""),";",REPT(" ",30)),91,30))),0)+IFERROR(VALUE(TRIM(MID(SUBSTITUTE(SUBSTITUTE(SUBSTITUTE(UPPER($P12)," ",""),"C",""),";",REPT(" ",30)),121,30))),0)+IFERROR(VALUE(TRIM(MID(SUBSTITUTE(SUBSTITUTE(SUBSTITUTE(UPPER($P12)," ",""),"C",""),";",REPT(" ",30)),151,30))),0)+IFERROR(VALUE(TRIM(MID(SUBSTITUTE(SUBSTITUTE(SUBSTITUTE(UPPER($P12)," ",""),"C",""),";",REPT(" ",30)),181,30))),0)+IFERROR(VALUE(TRIM(MID(SUBSTITUTE(SUBSTITUTE(SUBSTITUTE(UPPER($P12)," ",""),"C",""),";",REPT(" ",30)),211,30))),0))))) | V12: =IF($C12="","",IF($E12="Falta","-",MAX(0,MIN(10,5+IFERROR(VALUE(TRIM(MID(SUBSTITUTE(SUBSTITUTE(SUBSTITUTE(UPPER($T12)," ",""),"P",""),";",REPT(" ",30)),1,30))),0)+IFERROR(VALUE(TRIM(MID(SUBSTITUTE(SUBSTITUTE(SUBSTITUTE(UPPER($T12)," ",""),"P",""),";",REPT(" ",30)),31,30))),0)+IFERROR(VALUE(TRIM(MID(SUBSTITUTE(SUBSTITUTE(SUBSTITUTE(UPPER($T12)," ",""),"P",""),";",REPT(" ",30)),61,30))),0)+IFERROR(VALUE(TRIM(MID(SUBSTITUTE(SUBSTITUTE(SUBSTITUTE(UPPER($T12)," ",""),"P",""),";",REPT(" ",30)),91,30))),0)+IFERROR(VALUE(TRIM(MID(SUBSTITUTE(SUBSTITUTE(SUBSTITUTE(UPPER($T12)," ",""),"P",""),";",REPT(" ",30)),121,30))),0)+IFERROR(VALUE(TRIM(MID(SUBSTITUTE(SUBSTITUTE(SUBSTITUTE(UPPER($T12)," ",""),"P",""),";",REPT(" ",30)),151,30))),0)+IFERROR(VALUE(TRIM(MID(SUBSTITUTE(SUBSTITUTE(SUBSTITUTE(UPPER($T12)," ",""),"P",""),";",REPT(" ",30)),181,30))),0)+IFERROR(VALUE(TRIM(MID(SUBSTITUTE(SUBSTITUTE(SUBSTITUTE(UPPER($T12)," ",""),"P",""),";",REPT(" ",30)),211,30))),0)))))
A13: =IF($C13="","",2) | B13: =IF($C13="","","5ª Sessão") | C13: =IF(Preenchimento!$B$11="","",Preenchimento!$B$11) | D13: =IF($C13="","",IF(Preenchimento!$C$11="","-",Preenchimento!$C$11)) | J13: =IF($C13="","",IF($E13="Falta","-",MAX(0,MIN(10,8+IFERROR(VALUE(TRIM(MID(SUBSTITUTE(SUBSTITUTE(SUBSTITUTE(UPPER($H13)," ",""),"D",""),";",REPT(" ",30)),1,30))),0)+IFERROR(VALUE(TRIM(MID(SUBSTITUTE(SUBSTITUTE(SUBSTITUTE(UPPER($H13)," ",""),"D",""),";",REPT(" ",30)),31,30))),0)+IFERROR(VALUE(TRIM(MID(SUBSTITUTE(SUBSTITUTE(SUBSTITUTE(UPPER($H13)," ",""),"D",""),";",REPT(" ",30)),61,30))),0)+IFERROR(VALUE(TRIM(MID(SUBSTITUTE(SUBSTITUTE(SUBSTITUTE(UPPER($H13)," ",""),"D",""),";",REPT(" ",30)),91,30))),0)+IFERROR(VALUE(TRIM(MID(SUBSTITUTE(SUBSTITUTE(SUBSTITUTE(UPPER($H13)," ",""),"D",""),";",REPT(" ",30)),121,30))),0)+IFERROR(VALUE(TRIM(MID(SUBSTITUTE(SUBSTITUTE(SUBSTITUTE(UPPER($H13)," ",""),"D",""),";",REPT(" ",30)),151,30))),0)+IFERROR(VALUE(TRIM(MID(SUBSTITUTE(SUBSTITUTE(SUBSTITUTE(UPPER($H13)," ",""),"D",""),";",REPT(" ",30)),181,30))),0)+IFERROR(VALUE(TRIM(MID(SUBSTITUTE(SUBSTITUTE(SUBSTITUTE(UPPER($H13)," ",""),"D",""),";",REPT(" ",30)),211,30))),0))))) | N13: =IF($C13="","",IF($E13="Falta","-",MAX(0,MIN(10,8+IFERROR(VALUE(TRIM(MID(SUBSTITUTE(SUBSTITUTE(SUBSTITUTE(UPPER($L13)," ",""),"F",""),";",REPT(" ",30)),1,30))),0)+IFERROR(VALUE(TRIM(MID(SUBSTITUTE(SUBSTITUTE(SUBSTITUTE(UPPER($L13)," ",""),"F",""),";",REPT(" ",30)),31,30))),0)+IFERROR(VALUE(TRIM(MID(SUBSTITUTE(SUBSTITUTE(SUBSTITUTE(UPPER($L13)," ",""),"F",""),";",REPT(" ",30)),61,30))),0)+IFERROR(VALUE(TRIM(MID(SUBSTITUTE(SUBSTITUTE(SUBSTITUTE(UPPER($L13)," ",""),"F",""),";",REPT(" ",30)),91,30))),0)+IFERROR(VALUE(TRIM(MID(SUBSTITUTE(SUBSTITUTE(SUBSTITUTE(UPPER($L13)," ",""),"F",""),";",REPT(" ",30)),121,30))),0)+IFERROR(VALUE(TRIM(MID(SUBSTITUTE(SUBSTITUTE(SUBSTITUTE(UPPER($L13)," ",""),"F",""),";",REPT(" ",30)),151,30))),0)+IFERROR(VALUE(TRIM(MID(SUBSTITUTE(SUBSTITUTE(SUBSTITUTE(UPPER($L13)," ",""),"F",""),";",REPT(" ",30)),181,30))),0)+IFERROR(VALUE(TRIM(MID(SUBSTITUTE(SUBSTITUTE(SUBSTITUTE(UPPER($L13)," ",""),"F",""),";",REPT(" ",30)),211,30))),0))))) | R13: =IF($C13="","",IF($E13="Falta","-",MAX(0,MIN(10,5+IFERROR(VALUE(TRIM(MID(SUBSTITUTE(SUBSTITUTE(SUBSTITUTE(UPPER($P13)," ",""),"C",""),";",REPT(" ",30)),1,30))),0)+IFERROR(VALUE(TRIM(MID(SUBSTITUTE(SUBSTITUTE(SUBSTITUTE(UPPER($P13)," ",""),"C",""),";",REPT(" ",30)),31,30))),0)+IFERROR(VALUE(TRIM(MID(SUBSTITUTE(SUBSTITUTE(SUBSTITUTE(UPPER($P13)," ",""),"C",""),";",REPT(" ",30)),61,30))),0)+IFERROR(VALUE(TRIM(MID(SUBSTITUTE(SUBSTITUTE(SUBSTITUTE(UPPER($P13)," ",""),"C",""),";",REPT(" ",30)),91,30))),0)+IFERROR(VALUE(TRIM(MID(SUBSTITUTE(SUBSTITUTE(SUBSTITUTE(UPPER($P13)," ",""),"C",""),";",REPT(" ",30)),121,30))),0)+IFERROR(VALUE(TRIM(MID(SUBSTITUTE(SUBSTITUTE(SUBSTITUTE(UPPER($P13)," ",""),"C",""),";",REPT(" ",30)),151,30))),0)+IFERROR(VALUE(TRIM(MID(SUBSTITUTE(SUBSTITUTE(SUBSTITUTE(UPPER($P13)," ",""),"C",""),";",REPT(" ",30)),181,30))),0)+IFERROR(VALUE(TRIM(MID(SUBSTITUTE(SUBSTITUTE(SUBSTITUTE(UPPER($P13)," ",""),"C",""),";",REPT(" ",30)),211,30))),0))))) | V13: =IF($C13="","",IF($E13="Falta","-",MAX(0,MIN(10,5+IFERROR(VALUE(TRIM(MID(SUBSTITUTE(SUBSTITUTE(SUBSTITUTE(UPPER($T13)," ",""),"P",""),";",REPT(" ",30)),1,30))),0)+IFERROR(VALUE(TRIM(MID(SUBSTITUTE(SUBSTITUTE(SUBSTITUTE(UPPER($T13)," ",""),"P",""),";",REPT(" ",30)),31,30))),0)+IFERROR(VALUE(TRIM(MID(SUBSTITUTE(SUBSTITUTE(SUBSTITUTE(UPPER($T13)," ",""),"P",""),";",REPT(" ",30)),61,30))),0)+IFERROR(VALUE(TRIM(MID(SUBSTITUTE(SUBSTITUTE(SUBSTITUTE(UPPER($T13)," ",""),"P",""),";",REPT(" ",30)),91,30))),0)+IFERROR(VALUE(TRIM(MID(SUBSTITUTE(SUBSTITUTE(SUBSTITUTE(UPPER($T13)," ",""),"P",""),";",REPT(" ",30)),121,30))),0)+IFERROR(VALUE(TRIM(MID(SUBSTITUTE(SUBSTITUTE(SUBSTITUTE(UPPER($T13)," ",""),"P",""),";",REPT(" ",30)),151,30))),0)+IFERROR(VALUE(TRIM(MID(SUBSTITUTE(SUBSTITUTE(SUBSTITUTE(UPPER($T13)," ",""),"P",""),";",REPT(" ",30)),181,30))),0)+IFERROR(VALUE(TRIM(MID(SUBSTITUTE(SUBSTITUTE(SUBSTITUTE(UPPER($T13)," ",""),"P",""),";",REPT(" ",30)),211,30))),0)))))
A14: =IF($C14="","",3) | B14: =IF($C14="","","1ª Sessão") | C14: =IF(Preenchimento!$B$12="","",Preenchimento!$B$12) | D14: =IF($C14="","",IF(Preenchimento!$C$12="","-",Preenchimento!$C$12)) | J14: =IF($C14="","",IF($E14="Falta","-",MAX(0,MIN(10,8+IFERROR(VALUE(TRIM(MID(SUBSTITUTE(SUBSTITUTE(SUBSTITUTE(UPPER($H14)," ",""),"D",""),";",REPT(" ",30)),1,30))),0)+IFERROR(VALUE(TRIM(MID(SUBSTITUTE(SUBSTITUTE(SUBSTITUTE(UPPER($H14)," ",""),"D",""),";",REPT(" ",30)),31,30))),0)+IFERROR(VALUE(TRIM(MID(SUBSTITUTE(SUBSTITUTE(SUBSTITUTE(UPPER($H14)," ",""),"D",""),";",REPT(" ",30)),61,30))),0)+IFERROR(VALUE(TRIM(MID(SUBSTITUTE(SUBSTITUTE(SUBSTITUTE(UPPER($H14)," ",""),"D",""),";",REPT(" ",30)),91,30))),0)+IFERROR(VALUE(TRIM(MID(SUBSTITUTE(SUBSTITUTE(SUBSTITUTE(UPPER($H14)," ",""),"D",""),";",REPT(" ",30)),121,30))),0)+IFERROR(VALUE(TRIM(MID(SUBSTITUTE(SUBSTITUTE(SUBSTITUTE(UPPER($H14)," ",""),"D",""),";",REPT(" ",30)),151,30))),0)+IFERROR(VALUE(TRIM(MID(SUBSTITUTE(SUBSTITUTE(SUBSTITUTE(UPPER($H14)," ",""),"D",""),";",REPT(" ",30)),181,30))),0)+IFERROR(VALUE(TRIM(MID(SUBSTITUTE(SUBSTITUTE(SUBSTITUTE(UPPER($H14)," ",""),"D",""),";",REPT(" ",30)),211,30))),0))))) | N14: =IF($C14="","",IF($E14="Falta","-",MAX(0,MIN(10,8+IFERROR(VALUE(TRIM(MID(SUBSTITUTE(SUBSTITUTE(SUBSTITUTE(UPPER($L14)," ",""),"F",""),";",REPT(" ",30)),1,30))),0)+IFERROR(VALUE(TRIM(MID(SUBSTITUTE(SUBSTITUTE(SUBSTITUTE(UPPER($L14)," ",""),"F",""),";",REPT(" ",30)),31,30))),0)+IFERROR(VALUE(TRIM(MID(SUBSTITUTE(SUBSTITUTE(SUBSTITUTE(UPPER($L14)," ",""),"F",""),";",REPT(" ",30)),61,30))),0)+IFERROR(VALUE(TRIM(MID(SUBSTITUTE(SUBSTITUTE(SUBSTITUTE(UPPER($L14)," ",""),"F",""),";",REPT(" ",30)),91,30))),0)+IFERROR(VALUE(TRIM(MID(SUBSTITUTE(SUBSTITUTE(SUBSTITUTE(UPPER($L14)," ",""),"F",""),";",REPT(" ",30)),121,30))),0)+IFERROR(VALUE(TRIM(MID(SUBSTITUTE(SUBSTITUTE(SUBSTITUTE(UPPER($L14)," ",""),"F",""),";",REPT(" ",30)),151,30))),0)+IFERROR(VALUE(TRIM(MID(SUBSTITUTE(SUBSTITUTE(SUBSTITUTE(UPPER($L14)," ",""),"F",""),";",REPT(" ",30)),181,30))),0)+IFERROR(VALUE(TRIM(MID(SUBSTITUTE(SUBSTITUTE(SUBSTITUTE(UPPER($L14)," ",""),"F",""),";",REPT(" ",30)),211,30))),0))))) | R14: =IF($C14="","",IF($E14="Falta","-",MAX(0,MIN(10,5+IFERROR(VALUE(TRIM(MID(SUBSTITUTE(SUBSTITUTE(SUBSTITUTE(UPPER($P14)," ",""),"C",""),";",REPT(" ",30)),1,30))),0)+IFERROR(VALUE(TRIM(MID(SUBSTITUTE(SUBSTITUTE(SUBSTITUTE(UPPER($P14)," ",""),"C",""),";",REPT(" ",30)),31,30))),0)+IFERROR(VALUE(TRIM(MID(SUBSTITUTE(SUBSTITUTE(SUBSTITUTE(UPPER($P14)," ",""),"C",""),";",REPT(" ",30)),61,30))),0)+IFERROR(VALUE(TRIM(MID(SUBSTITUTE(SUBSTITUTE(SUBSTITUTE(UPPER($P14)," ",""),"C",""),";",REPT(" ",30)),91,30))),0)+IFERROR(VALUE(TRIM(MID(SUBSTITUTE(SUBSTITUTE(SUBSTITUTE(UPPER($P14)," ",""),"C",""),";",REPT(" ",30)),121,30))),0)+IFERROR(VALUE(TRIM(MID(SUBSTITUTE(SUBSTITUTE(SUBSTITUTE(UPPER($P14)," ",""),"C",""),";",REPT(" ",30)),151,30))),0)+IFERROR(VALUE(TRIM(MID(SUBSTITUTE(SUBSTITUTE(SUBSTITUTE(UPPER($P14)," ",""),"C",""),";",REPT(" ",30)),181,30))),0)+IFERROR(VALUE(TRIM(MID(SUBSTITUTE(SUBSTITUTE(SUBSTITUTE(UPPER($P14)," ",""),"C",""),";",REPT(" ",30)),211,30))),0))))) | V14: =IF($C14="","",IF($E14="Falta","-",MAX(0,MIN(10,5+IFERROR(VALUE(TRIM(MID(SUBSTITUTE(SUBSTITUTE(SUBSTITUTE(UPPER($T14)," ",""),"P",""),";",REPT(" ",30)),1,30))),0)+IFERROR(VALUE(TRIM(MID(SUBSTITUTE(SUBSTITUTE(SUBSTITUTE(UPPER($T14)," ",""),"P",""),";",REPT(" ",30)),31,30))),0)+IFERROR(VALUE(TRIM(MID(SUBSTITUTE(SUBSTITUTE(SUBSTITUTE(UPPER($T14)," ",""),"P",""),";",REPT(" ",30)),61,30))),0)+IFERROR(VALUE(TRIM(MID(SUBSTITUTE(SUBSTITUTE(SUBSTITUTE(UPPER($T14)," ",""),"P",""),";",REPT(" ",30)),91,30))),0)+IFERROR(VALUE(TRIM(MID(SUBSTITUTE(SUBSTITUTE(SUBSTITUTE(UPPER($T14)," ",""),"P",""),";",REPT(" ",30)),121,30))),0)+IFERROR(VALUE(TRIM(MID(SUBSTITUTE(SUBSTITUTE(SUBSTITUTE(UPPER($T14)," ",""),"P",""),";",REPT(" ",30)),151,30))),0)+IFERROR(VALUE(TRIM(MID(SUBSTITUTE(SUBSTITUTE(SUBSTITUTE(UPPER($T14)," ",""),"P",""),";",REPT(" ",30)),181,30))),0)+IFERROR(VALUE(TRIM(MID(SUBSTITUTE(SUBSTITUTE(SUBSTITUTE(UPPER($T14)," ",""),"P",""),";",REPT(" ",30)),211,30))),0)))))
A15: =IF($C15="","",3) | B15: =IF($C15="","","2ª Sessão") | C15: =IF(Preenchimento!$B$12="","",Preenchimento!$B$12) | D15: =IF($C15="","",IF(Preenchimento!$C$12="","-",Preenchimento!$C$12)) | J15: =IF($C15="","",IF($E15="Falta","-",MAX(0,MIN(10,8+IFERROR(VALUE(TRIM(MID(SUBSTITUTE(SUBSTITUTE(SUBSTITUTE(UPPER($H15)," ",""),"D",""),";",REPT(" ",30)),1,30))),0)+IFERROR(VALUE(TRIM(MID(SUBSTITUTE(SUBSTITUTE(SUBSTITUTE(UPPER($H15)," ",""),"D",""),";",REPT(" ",30)),31,30))),0)+IFERROR(VALUE(TRIM(MID(SUBSTITUTE(SUBSTITUTE(SUBSTITUTE(UPPER($H15)," ",""),"D",""),";",REPT(" ",30)),61,30))),0)+IFERROR(VALUE(TRIM(MID(SUBSTITUTE(SUBSTITUTE(SUBSTITUTE(UPPER($H15)," ",""),"D",""),";",REPT(" ",30)),91,30))),0)+IFERROR(VALUE(TRIM(MID(SUBSTITUTE(SUBSTITUTE(SUBSTITUTE(UPPER($H15)," ",""),"D",""),";",REPT(" ",30)),121,30))),0)+IFERROR(VALUE(TRIM(MID(SUBSTITUTE(SUBSTITUTE(SUBSTITUTE(UPPER($H15)," ",""),"D",""),";",REPT(" ",30)),151,30))),0)+IFERROR(VALUE(TRIM(MID(SUBSTITUTE(SUBSTITUTE(SUBSTITUTE(UPPER($H15)," ",""),"D",""),";",REPT(" ",30)),181,30))),0)+IFERROR(VALUE(TRIM(MID(SUBSTITUTE(SUBSTITUTE(SUBSTITUTE(UPPER($H15)," ",""),"D",""),";",REPT(" ",30)),211,30))),0))))) | N15: =IF($C15="","",IF($E15="Falta","-",MAX(0,MIN(10,8+IFERROR(VALUE(TRIM(MID(SUBSTITUTE(SUBSTITUTE(SUBSTITUTE(UPPER($L15)," ",""),"F",""),";",REPT(" ",30)),1,30))),0)+IFERROR(VALUE(TRIM(MID(SUBSTITUTE(SUBSTITUTE(SUBSTITUTE(UPPER($L15)," ",""),"F",""),";",REPT(" ",30)),31,30))),0)+IFERROR(VALUE(TRIM(MID(SUBSTITUTE(SUBSTITUTE(SUBSTITUTE(UPPER($L15)," ",""),"F",""),";",REPT(" ",30)),61,30))),0)+IFERROR(VALUE(TRIM(MID(SUBSTITUTE(SUBSTITUTE(SUBSTITUTE(UPPER($L15)," ",""),"F",""),";",REPT(" ",30)),91,30))),0)+IFERROR(VALUE(TRIM(MID(SUBSTITUTE(SUBSTITUTE(SUBSTITUTE(UPPER($L15)," ",""),"F",""),";",REPT(" ",30)),121,30))),0)+IFERROR(VALUE(TRIM(MID(SUBSTITUTE(SUBSTITUTE(SUBSTITUTE(UPPER($L15)," ",""),"F",""),";",REPT(" ",30)),151,30))),0)+IFERROR(VALUE(TRIM(MID(SUBSTITUTE(SUBSTITUTE(SUBSTITUTE(UPPER($L15)," ",""),"F",""),";",REPT(" ",30)),181,30))),0)+IFERROR(VALUE(TRIM(MID(SUBSTITUTE(SUBSTITUTE(SUBSTITUTE(UPPER($L15)," ",""),"F",""),";",REPT(" ",30)),211,30))),0))))) | R15: =IF($C15="","",IF($E15="Falta","-",MAX(0,MIN(10,5+IFERROR(VALUE(TRIM(MID(SUBSTITUTE(SUBSTITUTE(SUBSTITUTE(UPPER($P15)," ",""),"C",""),";",REPT(" ",30)),1,30))),0)+IFERROR(VALUE(TRIM(MID(SUBSTITUTE(SUBSTITUTE(SUBSTITUTE(UPPER($P15)," ",""),"C",""),";",REPT(" ",30)),31,30))),0)+IFERROR(VALUE(TRIM(MID(SUBSTITUTE(SUBSTITUTE(SUBSTITUTE(UPPER($P15)," ",""),"C",""),";",REPT(" ",30)),61,30))),0)+IFERROR(VALUE(TRIM(MID(SUBSTITUTE(SUBSTITUTE(SUBSTITUTE(UPPER($P15)," ",""),"C",""),";",REPT(" ",30)),91,30))),0)+IFERROR(VALUE(TRIM(MID(SUBSTITUTE(SUBSTITUTE(SUBSTITUTE(UPPER($P15)," ",""),"C",""),";",REPT(" ",30)),121,30))),0)+IFERROR(VALUE(TRIM(MID(SUBSTITUTE(SUBSTITUTE(SUBSTITUTE(UPPER($P15)," ",""),"C",""),";",REPT(" ",30)),151,30))),0)+IFERROR(VALUE(TRIM(MID(SUBSTITUTE(SUBSTITUTE(SUBSTITUTE(UPPER($P15)," ",""),"C",""),";",REPT(" ",30)),181,30))),0)+IFERROR(VALUE(TRIM(MID(SUBSTITUTE(SUBSTITUTE(SUBSTITUTE(UPPER($P15)," ",""),"C",""),";",REPT(" ",30)),211,30))),0))))) | V15: =IF($C15="","",IF($E15="Falta","-",MAX(0,MIN(10,5+IFERROR(VALUE(TRIM(MID(SUBSTITUTE(SUBSTITUTE(SUBSTITUTE(UPPER($T15)," ",""),"P",""),";",REPT(" ",30)),1,30))),0)+IFERROR(VALUE(TRIM(MID(SUBSTITUTE(SUBSTITUTE(SUBSTITUTE(UPPER($T15)," ",""),"P",""),";",REPT(" ",30)),31,30))),0)+IFERROR(VALUE(TRIM(MID(SUBSTITUTE(SUBSTITUTE(SUBSTITUTE(UPPER($T15)," ",""),"P",""),";",REPT(" ",30)),61,30))),0)+IFERROR(VALUE(TRIM(MID(SUBSTITUTE(SUBSTITUTE(SUBSTITUTE(UPPER($T15)," ",""),"P",""),";",REPT(" ",30)),91,30))),0)+IFERROR(VALUE(TRIM(MID(SUBSTITUTE(SUBSTITUTE(SUBSTITUTE(UPPER($T15)," ",""),"P",""),";",REPT(" ",30)),121,30))),0)+IFERROR(VALUE(TRIM(MID(SUBSTITUTE(SUBSTITUTE(SUBSTITUTE(UPPER($T15)," ",""),"P",""),";",REPT(" ",30)),151,30))),0)+IFERROR(VALUE(TRIM(MID(SUBSTITUTE(SUBSTITUTE(SUBSTITUTE(UPPER($T15)," ",""),"P",""),";",REPT(" ",30)),181,30))),0)+IFERROR(VALUE(TRIM(MID(SUBSTITUTE(SUBSTITUTE(SUBSTITUTE(UPPER($T15)," ",""),"P",""),";",REPT(" ",30)),211,30))),0)))))
A16: =IF($C16="","",3) | B16: =IF($C16="","","3ª Sessão") | C16: =IF(Preenchimento!$B$12="","",Preenchimento!$B$12) | D16: =IF($C16="","",IF(Preenchimento!$C$12="","-",Preenchimento!$C$12)) | J16: =IF($C16="","",IF($E16="Falta","-",MAX(0,MIN(10,8+IFERROR(VALUE(TRIM(MID(SUBSTITUTE(SUBSTITUTE(SUBSTITUTE(UPPER($H16)," ",""),"D",""),";",REPT(" ",30)),1,30))),0)+IFERROR(VALUE(TRIM(MID(SUBSTITUTE(SUBSTITUTE(SUBSTITUTE(UPPER($H16)," ",""),"D",""),";",REPT(" ",30)),31,30))),0)+IFERROR(VALUE(TRIM(MID(SUBSTITUTE(SUBSTITUTE(SUBSTITUTE(UPPER($H16)," ",""),"D",""),";",REPT(" ",30)),61,30))),0)+IFERROR(VALUE(TRIM(MID(SUBSTITUTE(SUBSTITUTE(SUBSTITUTE(UPPER($H16)," ",""),"D",""),";",REPT(" ",30)),91,30))),0)+IFERROR(VALUE(TRIM(MID(SUBSTITUTE(SUBSTITUTE(SUBSTITUTE(UPPER($H16)," ",""),"D",""),";",REPT(" ",30)),121,30))),0)+IFERROR(VALUE(TRIM(MID(SUBSTITUTE(SUBSTITUTE(SUBSTITUTE(UPPER($H16)," ",""),"D",""),";",REPT(" ",30)),151,30))),0)+IFERROR(VALUE(TRIM(MID(SUBSTITUTE(SUBSTITUTE(SUBSTITUTE(UPPER($H16)," ",""),"D",""),";",REPT(" ",30)),181,30))),0)+IFERROR(VALUE(TRIM(MID(SUBSTITUTE(SUBSTITUTE(SUBSTITUTE(UPPER($H16)," ",""),"D",""),";",REPT(" ",30)),211,30))),0))))) | N16: =IF($C16="","",IF($E16="Falta","-",MAX(0,MIN(10,8+IFERROR(VALUE(TRIM(MID(SUBSTITUTE(SUBSTITUTE(SUBSTITUTE(UPPER($L16)," ",""),"F",""),";",REPT(" ",30)),1,30))),0)+IFERROR(VALUE(TRIM(MID(SUBSTITUTE(SUBSTITUTE(SUBSTITUTE(UPPER($L16)," ",""),"F",""),";",REPT(" ",30)),31,30))),0)+IFERROR(VALUE(TRIM(MID(SUBSTITUTE(SUBSTITUTE(SUBSTITUTE(UPPER($L16)," ",""),"F",""),";",REPT(" ",30)),61,30))),0)+IFERROR(VALUE(TRIM(MID(SUBSTITUTE(SUBSTITUTE(SUBSTITUTE(UPPER($L16)," ",""),"F",""),";",REPT(" ",30)),91,30))),0)+IFERROR(VALUE(TRIM(MID(SUBSTITUTE(SUBSTITUTE(SUBSTITUTE(UPPER($L16)," ",""),"F",""),";",REPT(" ",30)),121,30))),0)+IFERROR(VALUE(TRIM(MID(SUBSTITUTE(SUBSTITUTE(SUBSTITUTE(UPPER($L16)," ",""),"F",""),";",REPT(" ",30)),151,30))),0)+IFERROR(VALUE(TRIM(MID(SUBSTITUTE(SUBSTITUTE(SUBSTITUTE(UPPER($L16)," ",""),"F",""),";",REPT(" ",30)),181,30))),0)+IFERROR(VALUE(TRIM(MID(SUBSTITUTE(SUBSTITUTE(SUBSTITUTE(UPPER($L16)," ",""),"F",""),";",REPT(" ",30)),211,30))),0))))) | R16: =IF($C16="","",IF($E16="Falta","-",MAX(0,MIN(10,5+IFERROR(VALUE(TRIM(MID(SUBSTITUTE(SUBSTITUTE(SUBSTITUTE(UPPER($P16)," ",""),"C",""),";",REPT(" ",30)),1,30))),0)+IFERROR(VALUE(TRIM(MID(SUBSTITUTE(SUBSTITUTE(SUBSTITUTE(UPPER($P16)," ",""),"C",""),";",REPT(" ",30)),31,30))),0)+IFERROR(VALUE(TRIM(MID(SUBSTITUTE(SUBSTITUTE(SUBSTITUTE(UPPER($P16)," ",""),"C",""),";",REPT(" ",30)),61,30))),0)+IFERROR(VALUE(TRIM(MID(SUBSTITUTE(SUBSTITUTE(SUBSTITUTE(UPPER($P16)," ",""),"C",""),";",REPT(" ",30)),91,30))),0)+IFERROR(VALUE(TRIM(MID(SUBSTITUTE(SUBSTITUTE(SUBSTITUTE(UPPER($P16)," ",""),"C",""),";",REPT(" ",30)),121,30))),0)+IFERROR(VALUE(TRIM(MID(SUBSTITUTE(SUBSTITUTE(SUBSTITUTE(UPPER($P16)," ",""),"C",""),";",REPT(" ",30)),151,30))),0)+IFERROR(VALUE(TRIM(MID(SUBSTITUTE(SUBSTITUTE(SUBSTITUTE(UPPER($P16)," ",""),"C",""),";",REPT(" ",30)),181,30))),0)+IFERROR(VALUE(TRIM(MID(SUBSTITUTE(SUBSTITUTE(SUBSTITUTE(UPPER($P16)," ",""),"C",""),";",REPT(" ",30)),211,30))),0))))) | V16: =IF($C16="","",IF($E16="Falta","-",MAX(0,MIN(10,5+IFERROR(VALUE(TRIM(MID(SUBSTITUTE(SUBSTITUTE(SUBSTITUTE(UPPER($T16)," ",""),"P",""),";",REPT(" ",30)),1,30))),0)+IFERROR(VALUE(TRIM(MID(SUBSTITUTE(SUBSTITUTE(SUBSTITUTE(UPPER($T16)," ",""),"P",""),";",REPT(" ",30)),31,30))),0)+IFERROR(VALUE(TRIM(MID(SUBSTITUTE(SUBSTITUTE(SUBSTITUTE(UPPER($T16)," ",""),"P",""),";",REPT(" ",30)),61,30))),0)+IFERROR(VALUE(TRIM(MID(SUBSTITUTE(SUBSTITUTE(SUBSTITUTE(UPPER($T16)," ",""),"P",""),";",REPT(" ",30)),91,30))),0)+IFERROR(VALUE(TRIM(MID(SUBSTITUTE(SUBSTITUTE(SUBSTITUTE(UPPER($T16)," ",""),"P",""),";",REPT(" ",30)),121,30))),0)+IFERROR(VALUE(TRIM(MID(SUBSTITUTE(SUBSTITUTE(SUBSTITUTE(UPPER($T16)," ",""),"P",""),";",REPT(" ",30)),151,30))),0)+IFERROR(VALUE(TRIM(MID(SUBSTITUTE(SUBSTITUTE(SUBSTITUTE(UPPER($T16)," ",""),"P",""),";",REPT(" ",30)),181,30))),0)+IFERROR(VALUE(TRIM(MID(SUBSTITUTE(SUBSTITUTE(SUBSTITUTE(UPPER($T16)," ",""),"P",""),";",REPT(" ",30)),211,30))),0)))))
